Workbook

Sheet LookUP
A2: Sessions Division | B2: Mewat at Nuh
A3: Total Courts | B3: =IF(B2="","",VLOOKUP(B2,Courts!B:F,5,FALSE())) -> 14
A4: Working Courts | B4: =IF(B2="","",VLOOKUP(B2,Courts!B:C,2,FALSE())) -> 13
A5: TJOs | B5: =IF(B2="","",VLOOKUP(B2,Courts!B:D,3,FALSE())) -> 1
A6: Family Camp Courts | B6: =IF(B2="","",VLOOKUP(B2,Courts!B:E,4,FALSE())) -> 0
A7: ITEM | B7: Scanners | C7: Display Boards | D7: MFP | E7: Duplex Laser Printers | F7: AIO | G7: PAS
A8: Distributed | B8: =IF(B2="","",VLOOKUP(B2,Scanners!B:L,11,FALSE())) -> 18 | C8: =IF(B2="","",VLOOKUP(B2,DisBo!B:I,8,FALSE())) -> 10 | D8: =IF(B2="","",VLOOKUP(B2,MFP!B:K,10,FALSE())) -> 14 | E8: =IF(B2="","",VLOOKUP(B2,DLP!B:O,14,FALSE())) -> 28 | F8: =IF(B2="","",VLOOKUP(B2,AIO!B:P,15,FALSE())) -> 112 | G8: =IF(B2="","",VLOOKUP(B2,PAS!B:J,9,FALSE())) -> 15
A9: Requirement | B9: =IF(B2="","",VLOOKUP(B2,Scanners!B:M,12,FALSE())) -> 14 | C9: =IF(B2="","",VLOOKUP(B2,DisBo!B:J,9,FALSE())) -> 14 | D9: =IF(B2="","",VLOOKUP(B2,MFP!B:L,11,FALSE())) -> 14 | E9: =IF(B2="","",VLOOKUP(B2,DLP!B:R,17,FALSE())) -> 28 | F9: =IF(B2="","",VLOOKUP(B2,AIO!B:T,19,FALSE())) -> 112 | G9: =IF(B2="","",VLOOKUP(B2,PAS!B:K,10,FALSE())) -> 14
A10: Shortfall (-) /Surplus (+) | B10: =IF(B2="","",VLOOKUP(B2,Scanners!B:N,13,FALSE())) -> 4 | C10: =IF(B2="","",VLOOKUP(B2,DisBo!B:K,10,FALSE())) -> -4 | D10: =IF(B2="","",VLOOKUP(B2,MFP!B:M,12,FALSE())) -> 0 | E10: =IF(B2="","",VLOOKUP(B2,DLP!B:S,18,FALSE())) -> 0 | F10: =IF(B2="","",VLOOKUP(B2,AIO!B:U,20,FALSE())) -> 0 | G10: =IF(B2="","",VLOOKUP(B2,PAS!B:L,11,FALSE())) -> 1
A12: PUNJAB
A13: Distributed | B13: =Scanners!L135 -> 786 | C13: =DisBo!I136 -> 572 | D13: =MFP!K135 -> 717 | E13: =DLP!O135 -> 1378 | F13: =AIO!P135 -> 4420
A14: Requirement | B14: =Scanners!M135 -> 685 | C14: =DisBo!J136 -> 685 | D14: =MFP!L135 -> 685 | E14: =DLP!R135 -> 1280 | F14: =AIO!T135 -> 5300
A15: Shortfall (-) /Surplus (+) | B15: =Scanners!N135 -> 101 | C15: =DisBo!K136 -> -113 | D15: =MFP!M135 -> 32 | E15: =DLP!S135 -> 98 | F15: =AIO!U135 -> -880
A17: HARYANA
A18: Distributed | B18: =Scanners!L136 -> 602 | C18: =DisBo!I137 -> 456 | D18: =MFP!K136 -> 548 | E18: =DLP!O136 -> 1095 | F18: =AIO!P136 -> 4241
A19: Requirement | B19: =Scanners!M136 -> 623 | C19: =DisBo!J137 -> 623 | D19: =MFP!L136 -> 623 | E19: =DLP!R136 -> 1174 | F19: =AIO!T136 -> 4840
A20: Shortfall (-) /Surplus (+) | B20: =Scanners!N136 -> -21 | C20: =DisBo!K137 -> -167 | D20: =MFP!M136 -> -75 | E20: =DLP!S136 -> -79 | F20: =AIO!U136 -> -599
A22: CHANDIGARH
A23: Distributed | B23: =Scanners!L137 -> 36 | C23: =DisBo!I138 -> 31 | D23: =MFP!K137 -> 31 | E23: =DLP!O137 -> 65 | F23: =AIO!P137 -> 240
A24: Requirement | B24: =Scanners!M137 -> 28 | C24: =DisBo!J138 -> 28 | D24: =MFP!L137 -> 28 | E24: =DLP!R137 -> 56 | F24: =AIO!T137 -> 224
A25: Shortfall (-) /Surplus (+) | B25: =Scanners!N137 -> 8 | C25: =DisBo!K138 -> 3 | D25: =MFP!M137 -> 3 | E25: =DLP!S137 -> 9 | F25: =AIO!U137 -> 16
A27: TOTAL
A28: Distributed | B28: =Scanners!L138 -> 1424 | C28: =DisBo!I139 -> 1059 | D28: =MFP!K138 -> 1296 | E28: =DLP!O138 -> 2538 | F28: =AIO!P138 -> 8901
A29: Requirement | B29: =Scanners!M138 -> 1336 | C29: =DisBo!J139 -> 1336 | D29: =MFP!L138 -> 1336 | E29: =DLP!R138 -> 2510 | F29: =AIO!T138 -> 10364
A30: Shortfall (-) /Surplus (+) | B30: =Scanners!N138 -> 88 | C30: =DisBo!K139 -> -277 | D30: =MFP!M138 -> -40 | E30: =DLP!S138 -> 28 | F30: =AIO!U138 -> -1463

Sheet TooliD
C1: Courts | G1: Scanners | J1: Display Boards | M1: Multi Function Printers | P1: Duplex Laser Printers | S1: AIO Computers with UPS | V1: Public Address System
A2: Sr. No. | B2: Sessions Division/Sub-Division | C2: Total number of working Court including family Courts | D2: TJOs | E2: Number of family Camp Court/ Gram Nyayalay | F2: Total COURTS | G2: Distributed | H2: Required | I2: Shortfall/Surplus | J2: Distributed | K2: Required | L2: Shortfall/Surplus | M2: Distributed | N2: Required | O2: Shortfall/Surplus | P2: Distributed | Q2: Required | R2: Shortfall/Surplus | S2: Distributed | T2: Required | U2: Shortfall/Surplus | V2: Distributed | W2: Required | X2: Shortfall/Surplus
A3: 1 | B3: Amritsar | C3: =VLOOKUP(B:B,Courts!B:C,2,FALSE) -> 48 | D3: =VLOOKUP(B:B,Courts!B:D,3,FALSE) -> 0 | E3: =VLOOKUP(B:B,Courts!B:E,4,FALSE) -> 0 | F3: =SUM(C3:E3) -> 48 | G3: =Scanners!L2 -> 51 | H3: =SUM(C3:E3)*1 -> 48 | I3: =G3-H3 -> 3 | J3: =DisBo!I2 -> 35 | K3: =SUM(C3:E3)*1 -> 48 | L3: =J3-K3 -> -13 | M3: =MFP!K2 -> 46 | N3: =SUM(C3:E3)*1 -> 48 | O3: =M3-N3 -> -2 | P3: =DLP!O2 -> 90 | Q3: =DLP!R2 -> 96 | R3: =P3-Q3 -> -6 | S3: =AIO!P2 -> 280 | T3: =SUM(C3:D3)*8+E3*4 -> 384 | U3: =S3-T3 -> -104 | V3: =PAS!J2 -> 35 | W3: =SUM(C3:E3)*1 -> 48 | X3: =V3-W3 -> -13
A4: 2 | B4: Ajnala | C4: =VLOOKUP(B:B,Courts!B:C,2,FALSE) -> 5 | D4: =VLOOKUP(B:B,Courts!B:D,3,FALSE) -> 0 | E4: =VLOOKUP(B:B,Courts!B:E,4,FALSE) -> 1 | F4: =SUM(C4:E4) -> 6 | G4: =Scanners!L3 -> 6 | H4: =SUM(C4:E4)*1 -> 6 | I4: =G4-H4 -> 0 | J4: =DisBo!I3 -> 5 | K4: =SUM(C4:E4)*1 -> 6 | L4: =J4-K4 -> -1 | M4: =MFP!K3 -> 6 | N4: =SUM(C4:E4)*1 -> 6 | O4: =M4-N4 -> 0 | P4: =DLP!O3 -> 11 | Q4: =DLP!R3 -> 10 | R4: =P4-Q4 -> 1 | S4: =AIO!P3 -> 36 | T4: =SUM(C4:D4)*8+E4*4 -> 44 | U4: =S4-T4 -> -8 | V4: =PAS!J3 -> 5 | W4: =SUM(C4:E4)*1 -> 6 | X4: =V4-W4 -> -1
A5: 3 | B5: Baba Bakala | C5: =VLOOKUP(B:B,Courts!B:C,2,FALSE) -> 4 | D5: =VLOOKUP(B:B,Courts!B:D,3,FALSE) -> 0 | E5: =VLOOKUP(B:B,Courts!B:E,4,FALSE) -> 1 | F5: =SUM(C5:E5) -> 5 | G5: =Scanners!L4 -> 5 | H5: =SUM(C5:E5)*1 -> 5 | I5: =G5-H5 -> 0 | J5: =DisBo!I4 -> 3 | K5: =SUM(C5:E5)*1 -> 5 | L5: =J5-K5 -> -2 | M5: =MFP!K4 -> 5 | N5: =SUM(C5:E5)*1 -> 5 | O5: =M5-N5 -> 0 | P5: =DLP!O4 -> 8 | Q5: =DLP!R4 -> 8 | R5: =P5-Q5 -> 0 | S5: =AIO!P4 -> 21 | T5: =SUM(C5:D5)*8+E5*4 -> 36 | U5: =S5-T5 -> -15 | V5: =PAS!J4 -> 2 | W5: =SUM(C5:E5)*1 -> 5 | X5: =V5-W5 -> -3
A6: 4 | B6: Barnala | C6: =VLOOKUP(B:B,Courts!B:C,2,FALSE) -> 11 | D6: =VLOOKUP(B:B,Courts!B:D,3,FALSE) -> 0 | E6: =VLOOKUP(B:B,Courts!B:E,4,FALSE) -> 0 | F6: =SUM(C6:E6) -> 11 | G6: =Scanners!L5 -> 17 | H6: =SUM(C6:E6)*1 -> 11 | I6: =G6-H6 -> 6 | J6: =DisBo!I5 -> 11 | K6: =SUM(C6:E6)*1 -> 11 | L6: =J6-K6 -> 0 | M6: =MFP!K5 -> 13 | N6: =SUM(C6:E6)*1 -> 11 | O6: =M6-N6 -> 2 | P6: =DLP!O5 -> 26 | Q6: =DLP!R5 -> 22 | R6: =P6-Q6 -> 4 | S6: =AIO!P5 -> 88 | T6: =SUM(C6:D6)*8+E6*4 -> 88 | U6: =S6-T6 -> 0 | V6: =PAS!J5 -> 11 | W6: =SUM(C6:E6)*1 -> 11 | X6: =V6-W6 -> 0
A7: 5 | B7: Bathinda | C7: =VLOOKUP(B:B,Courts!B:C,2,FALSE) -> 25 | D7: =VLOOKUP(B:B,Courts!B:D,3,FALSE) -> 0 | E7: =VLOOKUP(B:B,Courts!B:E,4,FALSE) -> 0 | F7: =SUM(C7:E7) -> 25 | G7: =Scanners!L6 -> 31 | H7: =SUM(C7:E7)*1 -> 25 | I7: =G7-H7 -> 6 | J7: =DisBo!I6 -> 20 | K7: =SUM(C7:E7)*1 -> 25 | L7: =J7-K7 -> -5 | M7: =MFP!K6 -> 28 | N7: =SUM(C7:E7)*1 -> 25 | O7: =M7-N7 -> 3 | P7: =DLP!O6 -> 54 | Q7: =DLP!R6 -> 50 | R7: =P7-Q7 -> 4 | S7: =AIO!P6 -> 168 | T7: =SUM(C7:D7)*8+E7*4 -> 200 | U7: =S7-T7 -> -32 | V7: =PAS!J6 -> 21 | W7: =SUM(C7:E7)*1 -> 25 | X7: =V7-W7 -> -4
A8: 6 | B8: Talwandi Sabo | C8: =VLOOKUP(B:B,Courts!B:C,2,FALSE) -> 6 | D8: =VLOOKUP(B:B,Courts!B:D,3,FALSE) -> 0 | E8: =VLOOKUP(B:B,Courts!B:E,4,FALSE) -> 1 | F8: =SUM(C8:E8) -> 7 | G8: =Scanners!L7 -> 7 | H8: =SUM(C8:E8)*1 -> 7 | I8: =G8-H8 -> 0 | J8: =DisBo!I7 -> 4 | K8: =SUM(C8:E8)*1 -> 7 | L8: =J8-K8 -> -3 | M8: =MFP!K7 -> 7 | N8: =SUM(C8:E8)*1 -> 7 | O8: =M8-N8 -> 0 | P8: =DLP!O7 -> 12 | Q8: =DLP!R7 -> 12 | R8: =P8-Q8 -> 0 | S8: =AIO!P7 -> 28 | T8: =SUM(C8:D8)*8+E8*4 -> 52 | U8: =S8-T8 -> -24 | V8: =PAS!J7 -> 4 | W8: =SUM(C8:E8)*1 -> 7 | X8: =V8-W8 -> -3
A9: 7 | B9: Phul | C9: =VLOOKUP(B:B,Courts!B:C,2,FALSE) -> 4 | D9: =VLOOKUP(B:B,Courts!B:D,3,FALSE) -> 0 | E9: =VLOOKUP(B:B,Courts!B:E,4,FALSE) -> 1 | F9: =SUM(C9:E9) -> 5 | G9: =Scanners!L8 -> 6 | H9: =SUM(C9:E9)*1 -> 5 | I9: =G9-H9 -> 1 | J9: =DisBo!I8 -> 3 | K9: =SUM(C9:E9)*1 -> 5 | L9: =J9-K9 -> -2 | M9: =MFP!K8 -> 6 | N9: =SUM(C9:E9)*1 -> 5 | O9: =M9-N9 -> 1 | P9: =DLP!O8 -> 10 | Q9: =DLP!R8 -> 8 | R9: =P9-Q9 -> 2 | S9: =AIO!P8 -> 21 | T9: =SUM(C9:D9)*8+E9*4 -> 36 | U9: =S9-T9 -> -15 | V9: =PAS!J8 -> 3 | W9: =SUM(C9:E9)*1 -> 5 | X9: =V9-W9 -> -2
A10: 8 | B10: Faridkot | C10: =VLOOKUP(B:B,Courts!B:C,2,FALSE) -> 12 | D10: =VLOOKUP(B:B,Courts!B:D,3,FALSE) -> 0 | E10: =VLOOKUP(B:B,Courts!B:E,4,FALSE) -> 0 | F10: =SUM(C10:E10) -> 12 | G10: =Scanners!L9 -> 14 | H10: =SUM(C10:E10)*1 -> 12 | I10: =G10-H10 -> 2 | J10: =DisBo!I9 -> 10 | K10: =SUM(C10:E10)*1 -> 12 | L10: =J10-K10 -> -2 | M10: =MFP!K9 -> 12 | N10: =SUM(C10:E10)*1 -> 12 | O10: =M10-N10 -> 0 | P10: =DLP!O9 -> 27 | Q10: =DLP!R9 -> 24 | R10: =P10-Q10 -> 3 | S10: =AIO!P9 -> 80 | T10: =SUM(C10:D10)*8+E10*4 -> 96 | U10: =S10-T10 -> -16 | V10: =PAS!J9 -> 11 | W10: =SUM(C10:E10)*1 -> 12 | X10: =V10-W10 -> -1
A11: 9 | B11: Jaitu | C11: =VLOOKUP(B:B,Courts!B:C,2,FALSE) -> 2 | D11: =VLOOKUP(B:B,Courts!B:D,3,FALSE) -> 0 | E11: =VLOOKUP(B:B,Courts!B:E,4,FALSE) -> 0 | F11: =SUM(C11:E11) -> 2 | G11: =Scanners!L10 -> 3 | H11: =SUM(C11:E11)*1 -> 2 | I11: =G11-H11 -> 1 | J11: =DisBo!I10 -> 1 | K11: =SUM(C11:E11)*1 -> 2 | L11: =J11-K11 -> -1 | M11: =MFP!K10 -> 2 | N11: =SUM(C11:E11)*1 -> 2 | O11: =M11-N11 -> 0 | P11: =DLP!O10 -> 4 | Q11: =DLP!R10 -> 4 | R11: =P11-Q11 -> 0 | S11: =AIO!P10 -> 8 | T11: =SUM(C11:D11)*8+E11*4 -> 16 | U11: =S11-T11 -> -8 | V11: =PAS!J10 -> 1 | W11: =SUM(C11:E11)*1 -> 2 | X11: =V11-W11 -> -1
A12: 10 | B12: Fatehgarh Sahib | C12: =VLOOKUP(B:B,Courts!B:C,2,FALSE) -> 11 | D12: =VLOOKUP(B:B,Courts!B:D,3,FALSE) -> 0 | E12: =VLOOKUP(B:B,Courts!B:E,4,FALSE) -> 0 | F12: =SUM(C12:E12) -> 11 | G12: =Scanners!L11 -> 14 | H12: =SUM(C12:E12)*1 -> 11 | I12: =G12-H12 -> 3 | J12: =DisBo!I11 -> 12 | K12: =SUM(C12:E12)*1 -> 11 | L12: =J12-K12 -> 1 | M12: =MFP!K11 -> 13 | N12: =SUM(C12:E12)*1 -> 11 | O12: =M12-N12 -> 2 | P12: =DLP!O11 -> 24 | Q12: =DLP!R11 -> 22 | R12: =P12-Q12 -> 2 | S12: =AIO!P11 -> 92 | T12: =SUM(C12:D12)*8+E12*4 -> 88 | U12: =S12-T12 -> 4 | V12: =PAS!J11 -> 12 | W12: =SUM(C12:E12)*1 -> 11 | X12: =V12-W12 -> 1
A13: 11 | B13: Amloh | C13: =VLOOKUP(B:B,Courts!B:C,2,FALSE) -> 4 | D13: =VLOOKUP(B:B,Courts!B:D,3,FALSE) -> 0 | E13: =VLOOKUP(B:B,Courts!B:E,4,FALSE) -> 1 | F13: =SUM(C13:E13) -> 5 | G13: =Scanners!L12 -> 6 | H13: =SUM(C13:E13)*1 -> 5 | I13: =G13-H13 -> 1 | J13: =DisBo!I12 -> 3 | K13: =SUM(C13:E13)*1 -> 5 | L13: =J13-K13 -> -2 | M13: =MFP!K12 -> 6 | N13: =SUM(C13:E13)*1 -> 5 | O13: =M13-N13 -> 1 | P13: =DLP!O12 -> 10 | Q13: =DLP!R12 -> 8 | R13: =P13-Q13 -> 2 | S13: =AIO!P12 -> 28 | T13: =SUM(C13:D13)*8+E13*4 -> 36 | U13: =S13-T13 -> -8 | V13: =PAS!J12 -> 3 | W13: =SUM(C13:E13)*1 -> 5 | X13: =V13-W13 -> -2
A14: 12 | B14: Khamanon | C14: =VLOOKUP(B:B,Courts!B:C,2,FALSE) -> 2 | D14: =VLOOKUP(B:B,Courts!B:D,3,FALSE) -> 0 | E14: =VLOOKUP(B:B,Courts!B:E,4,FALSE) -> 1 | F14: =SUM(C14:E14) -> 3 | G14: =Scanners!L13 -> 3 | H14: =SUM(C14:E14)*1 -> 3 | I14: =G14-H14 -> 0 | J14: =DisBo!I13 -> 3 | K14: =SUM(C14:E14)*1 -> 3 | L14: =J14-K14 -> 0 | M14: =MFP!K13 -> 3 | N14: =SUM(C14:E14)*1 -> 3 | O14: =M14-N14 -> 0 | P14: =DLP!O13 -> 4 | Q14: =DLP!R13 -> 4 | R14: =P14-Q14 -> 0 | S14: =AIO!P13 -> 20 | T14: =SUM(C14:D14)*8+E14*4 -> 20 | U14: =S14-T14 -> 0 | V14: =PAS!J13 -> 3 | W14: =SUM(C14:E14)*1 -> 3 | X14: =V14-W14 -> 0
... A132: 130 | B132: Bilaspur | C132: =VLOOKUP(B:B,Courts!B:C,2,FALSE) -> 4 | D132: =VLOOKUP(B:B,Courts!B:D,3,FALSE) -> 2 | E132: =VLOOKUP(B:B,Courts!B:E,4,FALSE) -> 1 | F132: =SUM(C132:E132) -> 7 | G132: =Scanners!L131 -> 4 | H132: =SUM(C132:E132)*1 -> 7 | I132: =G132-H132 -> -3 | J132: =DisBo!I131 -> 3 | K132: =SUM(C132:E132)*1 -> 7 | L132: =J132-K132 -> -4 | M132: =MFP!K131 -> 5 | N132: =SUM(C132:E132)*1 -> 7 | O132: =M132-N132 -> -2 | P132: =DLP!O131 -> 12 | Q132: =DLP!R131 -> 12 | R132: =P132-Q132 -> 0 | S132: =AIO!P131 -> 50 | T132: =SUM(C132:D132)*8+E132*4 -> 52 | U132: =S132-T132 -> -2 | V132: =PAS!J131 -> 5 | W132: =SUM(C132:E132)*1 -> 7 | X132: =V132-W132 -> -2
B134: Total | C134: =SUM(C3:C132) -> 1147 | D134: =SUM(D3:D132) -> 108 | E134: =SUM(E3:E132) -> 81 | F134: =SUM(F3:F132) -> 1336 | G134: =SUM(G3:G132) -> 1424 | H134: =SUM(H3:H132) -> 1336 | I134: =SUM(I3:I132) -> 88 | J134: =SUM(J3:J132) -> 1059 | ... X134: =SUM(X3:X132) -> -145
A136: 1 | B136: Punjab | C136: =SUM(C3:C70) -> 640 | D136: =SUM(D3:D70) -> 0 | E136: =SUM(E3:E70) -> 45 | F136: =SUM(F3:F70) -> 685 | G136: =SUM(G3:G70) -> 786 | H136: =SUM(H3:H70) -> 685 | I136: =SUM(I3:I70) -> 101 | J136: =SUM(J3:J70) -> 572 | ... X136: =SUM(X3:X70) -> -102
A137: 2 | B137: Haryana | C137: =SUM(C72:C132) -> 479 | D137: =SUM(D72:D132) -> 108 | E137: =SUM(E72:E132) -> 36 | F137: =SUM(F72:F132) -> 623 | G137: =SUM(G72:G132) -> 602 | H137: =SUM(H72:H132) -> 623 | I137: =SUM(I72:I132) -> -21 | J137: =SUM(J72:J132) -> 456 | ... X137: =SUM(X72:X132) -> -46
A138: 3 | B138: Chandigarh | C138: =C71 -> 28 | D138: =D71 -> 0 | E138: =E71 -> 0 | F138: =F71 -> 28 | G138: =G71 -> 36 | H138: =H71 -> 28 | I138: =I71 -> 8 | J138: =J71 -> 31 | ... X138: =X71 -> 3
B139: Total | C139: =SUM(C136:C138) -> 1147 | D139: =SUM(D136:D138) -> 108 | E139: =SUM(E136:E138) -> 81 | F139: =SUM(F136:F138) -> 1336 | G139: =SUM(G136:G138) -> 1424 | H139: =SUM(H136:H138) -> 1336 | I139: =SUM(I136:I138) -> 88 | J139: =SUM(J136:J138) -> 1059 | ... X139: =SUM(X136:X138) -> -145

Sheet Tooli
A1: State | B1: Session_Division | C1: Location_Name | D1: Location_Type | E1: Courts_Count | F1: Family_Courts | G1: TJOs | H1: Total_Courts | I1: Hardware_Item | J1: Required_Qty | K1: Distributed_Qty | L1: Balance_Qty | M1: Status | N1: Remarks
A2: Punjab | B2: Amritsar | C2: Amritsar | D2: Session | E2: =VLOOKUP(C:C,Courts!B:C,2,FALSE) -> 48 | F2: =VLOOKUP(C:C,Courts!B:E,4,FALSE) -> 0 | G2: =VLOOKUP(C:C,Courts!B:D,3,FALSE) -> 0 | H2: =VLOOKUP(C:C,Courts!B:F,5,FALSE) -> 48 | I2: Scanners | J2: =VLOOKUP(C:C,TooliD!B:H,7,FALSE) -> 48 | K2: =VLOOKUP(C:C,TooliD!B:G,6,FALSE) -> 51 | L2: =K2-J2 -> 3 | M2: =IF(L2=0,"OK", IF(L2>0,"Surplus","Shortfall")) -> Surplus
A3: Punjab | B3: Amritsar | C3: Amritsar | D3: Session | E3: =VLOOKUP(C:C,Courts!B:C,2,FALSE) -> 48 | F3: =VLOOKUP(C:C,Courts!B:E,4,FALSE) -> 0 | G3: =VLOOKUP(C:C,Courts!B:D,3,FALSE) -> 0 | H3: =VLOOKUP(C:C,Courts!B:F,5,FALSE) -> 48 | I3: Display Board | J3: =VLOOKUP(C:C,TooliD!B:K,7,FALSE) -> 48 | K3: =VLOOKUP(C:C,TooliD!B:J,9,FALSE) -> 35 | L3: =K3-J3 -> -13 | M3: =IF(L3=0,"OK", IF(L3>0,"Surplus","Shortfall")) -> Shortfall
A4: Punjab | B4: Amritsar | C4: Amritsar | D4: Session | E4: =VLOOKUP(C:C,Courts!B:C,2,FALSE) -> 48 | F4: =VLOOKUP(C:C,Courts!B:E,4,FALSE) -> 0 | G4: =VLOOKUP(C:C,Courts!B:D,3,FALSE) -> 0 | H4: =VLOOKUP(C:C,Courts!B:F,5,FALSE) -> 48 | I4: MFP | J4: =VLOOKUP(C:C,TooliD!B:N,13,FALSE) -> 48 | K4: =VLOOKUP(C:C,TooliD!B:M,12,FALSE) -> 46 | L4: =K4-J4 -> -2 | M4: =IF(L4=0,"OK", IF(L4>0,"Surplus","Shortfall")) -> Shortfall
A5: Punjab | B5: Amritsar | C5: Amritsar | D5: Session | E5: =VLOOKUP(C:C,Courts!B:C,2,FALSE) -> 48 | F5: =VLOOKUP(C:C,Courts!B:E,4,FALSE) -> 0 | G5: =VLOOKUP(C:C,Courts!B:D,3,FALSE) -> 0 | H5: =VLOOKUP(C:C,Courts!B:F,5,FALSE) -> 48 | I5: DLP | J5: =VLOOKUP(C:C,TooliD!B:Q,16,FALSE) -> 96 | K5: =VLOOKUP(C:C,TooliD!B:P,15,FALSE) -> 90 | L5: =K5-J5 -> -6 | M5: =IF(L5=0,"OK", IF(L5>0,"Surplus","Shortfall")) -> Shortfall
A6: Punjab | B6: Amritsar | C6: Amritsar | D6: Session | E6: =VLOOKUP(C:C,Courts!B:C,2,FALSE) -> 48 | F6: =VLOOKUP(C:C,Courts!B:E,4,FALSE) -> 0 | G6: =VLOOKUP(C:C,Courts!B:D,3,FALSE) -> 0 | H6: =VLOOKUP(C:C,Courts!B:F,5,FALSE) -> 48 | I6: AIO | J6: =VLOOKUP(C:C,TooliD!B:T,19,FALSE) -> 384 | K6: =VLOOKUP(C:C,TooliD!B:S,18,FALSE) -> 280 | L6: =K6-J6 -> -104 | M6: =IF(L6=0,"OK", IF(L6>0,"Surplus","Shortfall")) -> Shortfall
A7: Punjab | B7: Amritsar | C7: Amritsar | D7: Session | E7: =VLOOKUP(C:C,Courts!B:C,2,FALSE) -> 48 | F7: =VLOOKUP(C:C,Courts!B:E,4,FALSE) -> 0 | G7: =VLOOKUP(C:C,Courts!B:D,3,FALSE) -> 0 | H7: =VLOOKUP(C:C,Courts!B:F,5,FALSE) -> 48 | I7: PAS | J7: =VLOOKUP(C:C,TooliD!B:W,22,FALSE) -> 48 | K7: =VLOOKUP(C:C,TooliD!B:V,21,FALSE) -> 35 | L7: =K7-J7 -> -13 | M7: =IF(L7=0,"OK", IF(L7>0,"Surplus","Shortfall")) -> Shortfall
A8: Punjab | B8: Amritsar | C8: Ajnala | D8: SubDivision | E8: =VLOOKUP(C:C,Courts!B:C,2,FALSE) -> 5 | F8: =VLOOKUP(C:C,Courts!B:E,4,FALSE) -> 1 | G8: =VLOOKUP(C:C,Courts!B:D,3,FALSE) -> 0 | H8: =VLOOKUP(C:C,Courts!B:F,5,FALSE) -> 6 | I8: Scanners | J8: =VLOOKUP(C:C,TooliD!B:H,7,FALSE) -> 6 | K8: =VLOOKUP(C:C,TooliD!B:G,6,FALSE) -> 6 | L8: =K8-J8 -> 0 | M8: =IF(L8=0,"OK", IF(L8>0,"Surplus","Shortfall")) -> OK
A9: Punjab | B9: Amritsar | C9: Ajnala | D9: SubDivision | E9: =VLOOKUP(C:C,Courts!B:C,2,FALSE) -> 5 | F9: =VLOOKUP(C:C,Courts!B:E,4,FALSE) -> 1 | G9: =VLOOKUP(C:C,Courts!B:D,3,FALSE) -> 0 | H9: =VLOOKUP(C:C,Courts!B:F,5,FALSE) -> 6 | I9: Display Board | J9: =VLOOKUP(C:C,TooliD!B:K,7,FALSE) -> 6 | K9: =VLOOKUP(C:C,TooliD!B:J,9,FALSE) -> 5 | L9: =K9-J9 -> -1 | M9: =IF(L9=0,"OK", IF(L9>0,"Surplus","Shortfall")) -> Shortfall
A10: Punjab | B10: Amritsar | C10: Ajnala | D10: SubDivision | E10: =VLOOKUP(C:C,Courts!B:C,2,FALSE) -> 5 | F10: =VLOOKUP(C:C,Courts!B:E,4,FALSE) -> 1 | G10: =VLOOKUP(C:C,Courts!B:D,3,FALSE) -> 0 | H10: =VLOOKUP(C:C,Courts!B:F,5,FALSE) -> 6 | I10: MFP | J10: =VLOOKUP(C:C,TooliD!B:N,13,FALSE) -> 6 | K10: =VLOOKUP(C:C,TooliD!B:M,12,FALSE) -> 6 | L10: =K10-J10 -> 0 | M10: =IF(L10=0,"OK", IF(L10>0,"Surplus","Shortfall")) -> OK
A11: Punjab | B11: Amritsar | C11: Ajnala | D11: SubDivision | E11: =VLOOKUP(C:C,Courts!B:C,2,FALSE) -> 5 | F11: =VLOOKUP(C:C,Courts!B:E,4,FALSE) -> 1 | G11: =VLOOKUP(C:C,Courts!B:D,3,FALSE) -> 0 | H11: =VLOOKUP(C:C,Courts!B:F,5,FALSE) -> 6 | I11: DLP | J11: =VLOOKUP(C:C,TooliD!B:Q,16,FALSE) -> 10 | K11: =VLOOKUP(C:C,TooliD!B:P,15,FALSE) -> 11 | L11: =K11-J11 -> 1 | M11: =IF(L11=0,"OK", IF(L11>0,"Surplus","Shortfall")) -> Surplus
A12: Punjab | B12: Amritsar | C12: Ajnala | D12: SubDivision | E12: =VLOOKUP(C:C,Courts!B:C,2,FALSE) -> 5 | F12: =VLOOKUP(C:C,Courts!B:E,4,FALSE) -> 1 | G12: =VLOOKUP(C:C,Courts!B:D,3,FALSE) -> 0 | H12: =VLOOKUP(C:C,Courts!B:F,5,FALSE) -> 6 | I12: AIO | J12: =VLOOKUP(C:C,TooliD!B:T,19,FALSE) -> 44 | K12: =VLOOKUP(C:C,TooliD!B:S,18,FALSE) -> 36 | L12: =K12-J12 -> -8 | M12: =IF(L12=0,"OK", IF(L12>0,"Surplus","Shortfall")) -> Shortfall
A13: Punjab | B13: Amritsar | C13: Ajnala | D13: SubDivision | E13: =VLOOKUP(C:C,Courts!B:C,2,FALSE) -> 5 | F13: =VLOOKUP(C:C,Courts!B:E,4,FALSE) -> 1 | G13: =VLOOKUP(C:C,Courts!B:D,3,FALSE) -> 0 | H13: =VLOOKUP(C:C,Courts!B:F,5,FALSE) -> 6 | I13: PAS | J13: =VLOOKUP(C:C,TooliD!B:W,22,FALSE) -> 6 | K13: =VLOOKUP(C:C,TooliD!B:V,21,FALSE) -> 5 | L13: =K13-J13 -> -1 | M13: =IF(L13=0,"OK", IF(L13>0,"Surplus","Shortfall")) -> Shortfall
A14: Punjab | B14: Amritsar | C14: Baba Bakala | D14: SubDivision | E14: =VLOOKUP(C:C,Courts!B:C,2,FALSE) -> 4 | F14: =VLOOKUP(C:C,Courts!B:E,4,FALSE) -> 1 | G14: =VLOOKUP(C:C,Courts!B:D,3,FALSE) -> 0 | H14: =VLOOKUP(C:C,Courts!B:F,5,FALSE) -> 5 | I14: Scanners | J14: =VLOOKUP(C:C,TooliD!B:H,7,FALSE) -> 5 | K14: =VLOOKUP(C:C,TooliD!B:G,6,FALSE) -> 5 | L14: =K14-J14 -> 0 | M14: =IF(L14=0,"OK", IF(L14>0,"Surplus","Shortfall")) -> OK
A15: Punjab | B15: Amritsar | C15: Baba Bakala | D15: SubDivision | E15: =VLOOKUP(C:C,Courts!B:C,2,FALSE) -> 4 | F15: =VLOOKUP(C:C,Courts!B:E,4,FALSE) -> 1 | G15: =VLOOKUP(C:C,Courts!B:D,3,FALSE) -> 0 | H15: =VLOOKUP(C:C,Courts!B:F,5,FALSE) -> 5 | I15: Display Board | J15: =VLOOKUP(C:C,TooliD!B:K,7,FALSE) -> 5 | K15: =VLOOKUP(C:C,TooliD!B:J,9,FALSE) -> 3 | L15: =K15-J15 -> -2 | M15: =IF(L15=0,"OK", IF(L15>0,"Surplus","Shortfall")) -> Shortfall
A16: Punjab | B16: Amritsar | C16: Baba Bakala | D16: SubDivision | E16: =VLOOKUP(C:C,Courts!B:C,2,FALSE) -> 4 | F16: =VLOOKUP(C:C,Courts!B:E,4,FALSE) -> 1 | G16: =VLOOKUP(C:C,Courts!B:D,3,FALSE) -> 0 | H16: =VLOOKUP(C:C,Courts!B:F,5,FALSE) -> 5 | I16: MFP | J16: =VLOOKUP(C:C,TooliD!B:N,13,FALSE) -> 5 | K16: =VLOOKUP(C:C,TooliD!B:M,12,FALSE) -> 5 | L16: =K16-J16 -> 0 | M16: =IF(L16=0,"OK", IF(L16>0,"Surplus","Shortfall")) -> OK
A17: Punjab | B17: Amritsar | C17: Baba Bakala | D17: SubDivision | E17: =VLOOKUP(C:C,Courts!B:C,2,FALSE) -> 4 | F17: =VLOOKUP(C:C,Courts!B:E,4,FALSE) -> 1 | G17: =VLOOKUP(C:C,Courts!B:D,3,FALSE) -> 0 | H17: =VLOOKUP(C:C,Courts!B:F,5,FALSE) -> 5 | I17: DLP | J17: =VLOOKUP(C:C,TooliD!B:Q,16,FALSE) -> 8 | K17: =VLOOKUP(C:C,TooliD!B:P,15,FALSE) -> 8 | L17: =K17-J17 -> 0 | M17: =IF(L17=0,"OK", IF(L17>0,"Surplus","Shortfall")) -> OK
A18: Punjab | B18: Amritsar | C18: Baba Bakala | D18: SubDivision | E18: =VLOOKUP(C:C,Courts!B:C,2,FALSE) -> 4 | F18: =VLOOKUP(C:C,Courts!B:E,4,FALSE) -> 1 | G18: =VLOOKUP(C:C,Courts!B:D,3,FALSE) -> 0 | H18: =VLOOKUP(C:C,Courts!B:F,5,FALSE) -> 5 | I18: AIO | J18: =VLOOKUP(C:C,TooliD!B:T,19,FALSE) -> 36 | K18: =VLOOKUP(C:C,TooliD!B:S,18,FALSE) -> 21 | L18: =K18-J18 -> -15 | M18: =IF(L18=0,"OK", IF(L18>0,"Surplus","Shortfall")) -> Shortfall
A19: Punjab | B19: Amritsar | C19: Baba Bakala | D19: SubDivision | E19: =VLOOKUP(C:C,Courts!B:C,2,FALSE) -> 4 | F19: =VLOOKUP(C:C,Courts!B:E,4,FALSE) -> 1 | G19: =VLOOKUP(C:C,Courts!B:D,3,FALSE) -> 0 | H19: =VLOOKUP(C:C,Courts!B:F,5,FALSE) -> 5 | I19: PAS | J19: =VLOOKUP(C:C,TooliD!B:W,22,FALSE) -> 5 | K19: =VLOOKUP(C:C,TooliD!B:V,21,FALSE) -> 2 | L19: =K19-J19 -> -3 | M19: =IF(L19=0,"OK", IF(L19>0,"Surplus","Shortfall")) -> Shortfall
A20: Punjab | B20: Barnala | C20: Barnala | D20: Session | E20: =VLOOKUP(C:C,Courts!B:C,2,FALSE) -> 11 | F20: =VLOOKUP(C:C,Courts!B:E,4,FALSE) -> 0 | G20: =VLOOKUP(C:C,Courts!B:D,3,FALSE) -> 0 | H20: =VLOOKUP(C:C,Courts!B:F,5,FALSE) -> 11 | I20: Scanners | J20: =VLOOKUP(C:C,TooliD!B:H,7,FALSE) -> 11 | K20: =VLOOKUP(C:C,TooliD!B:G,6,FALSE) -> 17 | L20: =K20-J20 -> 6 | M20: =IF(L20=0,"OK", IF(L20>0,"Surplus","Shortfall")) -> Surplus
A21: Punjab | B21: Barnala | C21: Barnala | D21: Session | E21: =VLOOKUP(C:C,Courts!B:C,2,FALSE) -> 11 | F21: =VLOOKUP(C:C,Courts!B:E,4,FALSE) -> 0 | G21: =VLOOKUP(C:C,Courts!B:D,3,FALSE) -> 0 | H21: =VLOOKUP(C:C,Courts!B:F,5,FALSE) -> 11 | I21: Display Board | J21: =VLOOKUP(C:C,TooliD!B:K,7,FALSE) -> 11 | K21: =VLOOKUP(C:C,TooliD!B:J,9,FALSE) -> 11 | L21: =K21-J21 -> 0 | M21: =IF(L21=0,"OK", IF(L21>0,"Surplus","Shortfall")) -> OK
A22: Punjab | B22: Barnala | C22: Barnala | D22: Session | E22: =VLOOKUP(C:C,Courts!B:C,2,FALSE) -> 11 | F22: =VLOOKUP(C:C,Courts!B:E,4,FALSE) -> 0 | G22: =VLOOKUP(C:C,Courts!B:D,3,FALSE) -> 0 | H22: =VLOOKUP(C:C,Courts!B:F,5,FALSE) -> 11 | I22: MFP | J22: =VLOOKUP(C:C,TooliD!B:N,13,FALSE) -> 11 | K22: =VLOOKUP(C:C,TooliD!B:M,12,FALSE) -> 13 | L22: =K22-J22 -> 2 | M22: =IF(L22=0,"OK", IF(L22>0,"Surplus","Shortfall")) -> Surplus
A23: Punjab | B23: Barnala | C23: Barnala | D23: Session | E23: =VLOOKUP(C:C,Courts!B:C,2,FALSE) -> 11 | F23: =VLOOKUP(C:C,Courts!B:E,4,FALSE) -> 0 | G23: =VLOOKUP(C:C,Courts!B:D,3,FALSE) -> 0 | H23: =VLOOKUP(C:C,Courts!B:F,5,FALSE) -> 11 | I23: DLP | J23: =VLOOKUP(C:C,TooliD!B:Q,16,FALSE) -> 22 | K23: =VLOOKUP(C:C,TooliD!B:P,15,FALSE) -> 26 | L23: =K23-J23 -> 4 | M23: =IF(L23=0,"OK", IF(L23>0,"Surplus","Shortfall")) -> Surplus
A24: Punjab | B24: Barnala | C24: Barnala | D24: Session | E24: =VLOOKUP(C:C,Courts!B:C,2,FALSE) -> 11 | F24: =VLOOKUP(C:C,Courts!B:E,4,FALSE) -> 0 | G24: =VLOOKUP(C:C,Courts!B:D,3,FALSE) -> 0 | H24: =VLOOKUP(C:C,Courts!B:F,5,FALSE) -> 11 | I24: AIO | J24: =VLOOKUP(C:C,TooliD!B:T,19,FALSE) -> 88 | K24: =VLOOKUP(C:C,TooliD!B:S,18,FALSE) -> 88 | L24: =K24-J24 -> 0 | M24: =IF(L24=0,"OK", IF(L24>0,"Surplus","Shortfall")) -> OK
A25: Punjab | B25: Barnala | C25: Barnala | D25: Session | E25: =VLOOKUP(C:C,Courts!B:C,2,FALSE) -> 11 | F25: =VLOOKUP(C:C,Courts!B:E,4,FALSE) -> 0 | G25: =VLOOKUP(C:C,Courts!B:D,3,FALSE) -> 0 | H25: =VLOOKUP(C:C,Courts!B:F,5,FALSE) -> 11 | I25: PAS | J25: =VLOOKUP(C:C,TooliD!B:W,22,FALSE) -> 11 | K25: =VLOOKUP(C:C,TooliD!B:V,21,FALSE) -> 11 | L25: =K25-J25 -> 0 | M25: =IF(L25=0,"OK", IF(L25>0,"Surplus","Shortfall")) -> OK
A26: Punjab | B26: Bathinda | C26: Bathinda | D26: Session | E26: =VLOOKUP(C:C,Courts!B:C,2,FALSE) -> 25 | F26: =VLOOKUP(C:C,Courts!B:E,4,FALSE) -> 0 | G26: =VLOOKUP(C:C,Courts!B:D,3,FALSE) -> 0 | H26: =VLOOKUP(C:C,Courts!B:F,5,FALSE) -> 25 | I26: Scanners | J26: =VLOOKUP(C:C,TooliD!B:H,7,FALSE) -> 25 | K26: =VLOOKUP(C:C,TooliD!B:G,6,FALSE) -> 31 | L26: =K26-J26 -> 6 | M26: =IF(L26=0,"OK", IF(L26>0,"Surplus","Shortfall")) -> Surplus
A27: Punjab | B27: Bathinda | C27: Bathinda | D27: Session | E27: =VLOOKUP(C:C,Courts!B:C,2,FALSE) -> 25 | F27: =VLOOKUP(C:C,Courts!B:E,4,FALSE) -> 0 | G27: =VLOOKUP(C:C,Courts!B:D,3,FALSE) -> 0 | H27: =VLOOKUP(C:C,Courts!B:F,5,FALSE) -> 25 | I27: Display Board | J27: =VLOOKUP(C:C,TooliD!B:K,7,FALSE) -> 25 | K27: =VLOOKUP(C:C,TooliD!B:J,9,FALSE) -> 20 | L27: =K27-J27 -> -5 | M27: =IF(L27=0,"OK", IF(L27>0,"Surplus","Shortfall")) -> Shortfall
A28: Punjab | B28: Bathinda | C28: Bathinda | D28: Session | E28: =VLOOKUP(C:C,Courts!B:C,2,FALSE) -> 25 | F28: =VLOOKUP(C:C,Courts!B:E,4,FALSE) -> 0 | G28: =VLOOKUP(C:C,Courts!B:D,3,FALSE) -> 0 | H28: =VLOOKUP(C:C,Courts!B:F,5,FALSE) -> 25 | I28: MFP | J28: =VLOOKUP(C:C,TooliD!B:N,13,FALSE) -> 25 | K28: =VLOOKUP(C:C,TooliD!B:M,12,FALSE) -> 28 | L28: =K28-J28 -> 3 | M28: =IF(L28=0,"OK", IF(L28>0,"Surplus","Shortfall")) -> Surplus
A29: Punjab | B29: Bathinda | C29: Bathinda | D29: Session | E29: =VLOOKUP(C:C,Courts!B:C,2,FALSE) -> 25 | F29: =VLOOKUP(C:C,Courts!B:E,4,FALSE) -> 0 | G29: =VLOOKUP(C:C,Courts!B:D,3,FALSE) -> 0 | H29: =VLOOKUP(C:C,Courts!B:F,5,FALSE) -> 25 | I29: DLP | J29: =VLOOKUP(C:C,TooliD!B:Q,16,FALSE) -> 50 | K29: =VLOOKUP(C:C,TooliD!B:P,15,FALSE) -> 54 | L29: =K29-J29 -> 4 | M29: =IF(L29=0,"OK", IF(L29>0,"Surplus","Shortfall")) -> Surplus
A30: Punjab | B30: Bathinda | C30: Bathinda | D30: Session | E30: =VLOOKUP(C:C,Courts!B:C,2,FALSE) -> 25 | F30: =VLOOKUP(C:C,Courts!B:E,4,FALSE) -> 0 | G30: =VLOOKUP(C:C,Courts!B:D,3,FALSE) -> 0 | H30: =VLOOKUP(C:C,Courts!B:F,5,FALSE) -> 25 | I30: AIO | J30: =VLOOKUP(C:C,TooliD!B:T,19,FALSE) -> 200 | K30: =VLOOKUP(C:C,TooliD!B:S,18,FALSE) -> 168 | L30: =K30-J30 -> -32 | M30: =IF(L30=0,"OK", IF(L30>0,"Surplus","Shortfall")) -> Shortfall
A31: Punjab | B31: Bathinda | C31: Bathinda | D31: Session | E31: =VLOOKUP(C:C,Courts!B:C,2,FALSE) -> 25 | F31: =VLOOKUP(C:C,Courts!B:E,4,FALSE) -> 0 | G31: =VLOOKUP(C:C,Courts!B:D,3,FALSE) -> 0 | H31: =VLOOKUP(C:C,Courts!B:F,5,FALSE) -> 25 | I31: PAS | J31: =VLOOKUP(C:C,TooliD!B:W,22,FALSE) -> 25 | K31: =VLOOKUP(C:C,TooliD!B:V,21,FALSE) -> 21 | L31: =K31-J31 -> -4 | M31: =IF(L31=0,"OK", IF(L31>0,"Surplus","Shortfall")) -> Shortfall
A32: Punjab | B32: Bathinda | C32: Talwandi Sabo | D32: SubDivision | E32: =VLOOKUP(C:C,Courts!B:C,2,FALSE) -> 6 | F32: =VLOOKUP(C:C,Courts!B:E,4,FALSE) -> 1 | G32: =VLOOKUP(C:C,Courts!B:D,3,FALSE) -> 0 | H32: =VLOOKUP(C:C,Courts!B:F,5,FALSE) -> 7 | I32: Scanners | J32: =VLOOKUP(C:C,TooliD!B:H,7,FALSE) -> 7 | K32: =VLOOKUP(C:C,TooliD!B:G,6,FALSE) -> 7 | L32: =K32-J32 -> 0 | M32: =IF(L32=0,"OK", IF(L32>0,"Surplus","Shortfall")) -> OK
A33: Punjab | B33: Bathinda | C33: Talwandi Sabo | D33: SubDivision | E33: =VLOOKUP(C:C,Courts!B:C,2,FALSE) -> 6 | F33: =VLOOKUP(C:C,Courts!B:E,4,FALSE) -> 1 | G33: =VLOOKUP(C:C,Courts!B:D,3,FALSE) -> 0 | H33: =VLOOKUP(C:C,Courts!B:F,5,FALSE) -> 7 | I33: Display Board | J33: =VLOOKUP(C:C,TooliD!B:K,7,FALSE) -> 7 | K33: =VLOOKUP(C:C,TooliD!B:J,9,FALSE) -> 4 | L33: =K33-J33 -> -3 | M33: =IF(L33=0,"OK", IF(L33>0,"Surplus","Shortfall")) -> Shortfall
A34: Punjab | B34: Bathinda | C34: Talwandi Sabo | D34: SubDivision | E34: =VLOOKUP(C:C,Courts!B:C,2,FALSE) -> 6 | F34: =VLOOKUP(C:C,Courts!B:E,4,FALSE) -> 1 | G34: =VLOOKUP(C:C,Courts!B:D,3,FALSE) -> 0 | H34: =VLOOKUP(C:C,Courts!B:F,5,FALSE) -> 7 | I34: MFP | J34: =VLOOKUP(C:C,TooliD!B:N,13,FALSE) -> 7 | K34: =VLOOKUP(C:C,TooliD!B:M,12,FALSE) -> 7 | L34: =K34-J34 -> 0 | M34: =IF(L34=0,"OK", IF(L34>0,"Surplus","Shortfall")) -> OK
A35: Punjab | B35: Bathinda | C35: Talwandi Sabo | D35: SubDivision | E35: =VLOOKUP(C:C,Courts!B:C,2,FALSE) -> 6 | F35: =VLOOKUP(C:C,Courts!B:E,4,FALSE) -> 1 | G35: =VLOOKUP(C:C,Courts!B:D,3,FALSE) -> 0 | H35: =VLOOKUP(C:C,Courts!B:F,5,FALSE) -> 7 | I35: DLP | J35: =VLOOKUP(C:C,TooliD!B:Q,16,FALSE) -> 12 | K35: =VLOOKUP(C:C,TooliD!B:P,15,FALSE) -> 12 | L35: =K35-J35 -> 0 | M35: =IF(L35=0,"OK", IF(L35>0,"Surplus","Shortfall")) -> OK
A36: Punjab | B36: Bathinda | C36: Talwandi Sabo | D36: SubDivision | E36: =VLOOKUP(C:C,Courts!B:C,2,FALSE) -> 6 | F36: =VLOOKUP(C:C,Courts!B:E,4,FALSE) -> 1 | G36: =VLOOKUP(C:C,Courts!B:D,3,FALSE) -> 0 | H36: =VLOOKUP(C:C,Courts!B:F,5,FALSE) -> 7 | I36: AIO | J36: =VLOOKUP(C:C,TooliD!B:T,19,FALSE) -> 52 | K36: =VLOOKUP(C:C,TooliD!B:S,18,FALSE) -> 28 | L36: =K36-J36 -> -24 | M36: =IF(L36=0,"OK", IF(L36>0,"Surplus","Shortfall")) -> Shortfall
A37: Punjab | B37: Bathinda | C37: Talwandi Sabo | D37: SubDivision | E37: =VLOOKUP(C:C,Courts!B:C,2,FALSE) -> 6 | F37: =VLOOKUP(C:C,Courts!B:E,4,FALSE) -> 1 | G37: =VLOOKUP(C:C,Courts!B:D,3,FALSE) -> 0 | H37: =VLOOKUP(C:C,Courts!B:F,5,FALSE) -> 7 | I37: PAS | J37: =VLOOKUP(C:C,TooliD!B:W,22,FALSE) -> 7 | K37: =VLOOKUP(C:C,TooliD!B:V,21,FALSE) -> 4 | L37: =K37-J37 -> -3 | M37: =IF(L37=0,"OK", IF(L37>0,"Surplus","Shortfall")) -> Shortfall
A38: Punjab | B38: Bathinda | C38: Phul | D38: SubDivision | E38: =VLOOKUP(C:C,Courts!B:C,2,FALSE) -> 4 | F38: =VLOOKUP(C:C,Courts!B:E,4,FALSE) -> 1 | G38: =VLOOKUP(C:C,Courts!B:D,3,FALSE) -> 0 | H38: =VLOOKUP(C:C,Courts!B:F,5,FALSE) -> 5 | I38: Scanners | J38: =VLOOKUP(C:C,TooliD!B:H,7,FALSE) -> 5 | K38: =VLOOKUP(C:C,TooliD!B:G,6,FALSE) -> 6 | L38: =K38-J38 -> 1 | M38: =IF(L38=0,"OK", IF(L38>0,"Surplus","Shortfall")) -> Surplus
A39: Punjab | B39: Bathinda | C39: Phul | D39: SubDivision | E39: =VLOOKUP(C:C,Courts!B:C,2,FALSE) -> 4 | F39: =VLOOKUP(C:C,Courts!B:E,4,FALSE) -> 1 | G39: =VLOOKUP(C:C,Courts!B:D,3,FALSE) -> 0 | H39: =VLOOKUP(C:C,Courts!B:F,5,FALSE) -> 5 | I39: Display Board | J39: =VLOOKUP(C:C,TooliD!B:K,7,FALSE) -> 5 | K39: =VLOOKUP(C:C,TooliD!B:J,9,FALSE) -> 3 | L39: =K39-J39 -> -2 | M39: =IF(L39=0,"OK", IF(L39>0,"Surplus","Shortfall")) -> Shortfall
A40: Punjab | B40: Bathinda | C40: Phul | D40: SubDivision | E40: =VLOOKUP(C:C,Courts!B:C,2,FALSE) -> 4 | F40: =VLOOKUP(C:C,Courts!B:E,4,FALSE) -> 1 | G40: =VLOOKUP(C:C,Courts!B:D,3,FALSE) -> 0 | H40: =VLOOKUP(C:C,Courts!B:F,5,FALSE) -> 5 | I40: MFP | J40: =VLOOKUP(C:C,TooliD!B:N,13,FALSE) -> 5 | K40: =VLOOKUP(C:C,TooliD!B:M,12,FALSE) -> 6 | L40: =K40-J40 -> 1 | M40: =IF(L40=0,"OK", IF(L40>0,"Surplus","Shortfall")) -> Surplus
...

Sheet Courts
A1: Sr. No. | B1: Sessions Division/Sub-Division | C1: Total number of working Court including family Courts (excluding Officers working as Secy, DLSA, ADJ/ ACJ as Spl. Judge, CBI Court & SJM, POIT/ Special Tribunal/ Railway Magistrate) as on 28.11.2025 | D1: TJOs | E1: Number of family Camp Court/ Gram Nyayalaya updated as on 28.11.2025 | F1: Total Courts
A2: 1 | B2: Amritsar | C2: 48 | D2: 0 | E2: 0 | F2: =SUM(C2:E2) -> 48
A3: 2 | B3: Ajnala | C3: 5 | D3: 0 | E3: 1 | F3: =SUM(C3:E3) -> 6
A4: 3 | B4: Baba Bakala | C4: 4 | D4: 0 | E4: 1 | F4: =SUM(C4:E4) -> 5
A5: 4 | B5: Barnala | C5: 11 | D5: 0 | E5: 0 | F5: =SUM(C5:E5) -> 11
A6: 5 | B6: Bathinda | C6: 25 | D6: 0 | E6: 0 | F6: =SUM(C6:E6) -> 25
A7: 6 | B7: Talwandi Sabo | C7: 6 | D7: 0 | E7: 1 | F7: =SUM(C7:E7) -> 7
A8: 7 | B8: Phul | C8: 4 | D8: 0 | E8: 1 | F8: =SUM(C8:E8) -> 5
A9: 8 | B9: Faridkot | C9: 12 | D9: 0 | E9: 0 | F9: =SUM(C9:E9) -> 12
A10: 9 | B10: Jaitu | C10: 2 | D10: 0 | E10: 0 | F10: =SUM(C10:E10) -> 2
A11: 10 | B11: Fatehgarh Sahib | C11: 11 | D11: 0 | E11: 0 | F11: =SUM(C11:E11) -> 11
A12: 11 | B12: Amloh | C12: 4 | D12: 0 | E12: 1 | F12: =SUM(C12:E12) -> 5
A13: 12 | B13: Khamanon | C13: 2 | D13: 0 | E13: 1 | F13: =SUM(C13:E13) -> 3
... A131: 130 | B131: Bilaspur | C131: 4 | D131: 2 | E131: 1 | F131: =SUM(C131:E131) -> 7
B133: Total | C133: =SUM(C2:C131) -> 1147 | D133: =SUM(D2:D131) -> 108 | E133: =SUM(E2:E131) -> 81 | F133: =SUM(F2:F131) -> 1336
A135: 1 | B135: Punjab | C135: =SUM(C2:C69) -> 640 | D135: =SUM(D2:D69) -> 0 | E135: =SUM(E2:E69) -> 45 | F135: =SUM(F2:F69) -> 685
A136: 2 | B136: Haryana | C136: =SUM(C71:C131) -> 479 | D136: =SUM(D71:D131) -> 108 | E136: =SUM(E71:E131) -> 36 | F136: =SUM(F71:F131) -> 623
A137: 3 | B137: Chandigarh | C137: =C70 -> 28 | D137: =D70 -> 0 | E137: =E70 -> 0 | F137: =F70 -> 28
B138: Total | C138: =SUM(C135:C137) -> 1147 | D138: =SUM(D135:D137) -> 108 | E138: =SUM(E135:E137) -> 81 | F138: =SUM(F135:F137) -> 1336

Sheet MFP
A1: Sr. No. | B1: Sessions Division/Sub-Division | C1: (A) Total number of working Court including family Courts (excluding Officers working as Secy, DLSA, ADJ/ ACJ as Spl. Judge, CBI Court & SJM, POIT/ Special Tribunal/ Railway Magistrate) as on 28.11.2025 | D1: (B) Number of family Camp Court/ Gram Nyayalaya updated as on 28.11.2025 | E1: (C) TJOs | F1: 2017 | G1: 2020 | H1: 2023 | I1: Supplied for Courts in 2025 | J1: Supplied for eSewa Kendras in 2025 | K1: (D) Total distributed for Court Use (under warranty & AMC) | L1: E= (A+B+C) x 1 Requirement 1 per Court & 1 per gram nyayalya and family camp court and TJOs | M1: F= D - E Surplus (+) / Shortfall (-) | N1: Requirement after adjustment within Session Division
A2: 1 | B2: Amritsar | C2: =VLOOKUP(B:B,Courts!B:C,2,FALSE()) -> 48 | D2: =VLOOKUP(B:B,Courts!B:E,4,FALSE()) -> 0 | E2: =VLOOKUP(B:B,Courts!B:D,3,FALSE()) -> 0 | F2: 34 | G2: 0 | H2: 0 | I2: 12 | J2: 1 | K2: =SUM(F2:I2) -> 46 | L2: =SUM(C2:E2)*1 -> 48 | M2: =K2-L2 -> -2 | N2: 2
A3: 2 | B3: Ajnala | C3: =VLOOKUP(B:B,Courts!B:C,2,FALSE()) -> 5 | D3: =VLOOKUP(B:B,Courts!B:E,4,FALSE()) -> 1 | E3: =VLOOKUP(B:B,Courts!B:D,3,FALSE()) -> 0 | F3: 4 | G3: 0 | H3: 0 | I3: 2 | J3: 1 | K3: =SUM(F3:I3) -> 6 | L3: =SUM(C3:E3)*1 -> 6 | M3: =K3-L3 -> 0 | N3: 0
A4: 3 | B4: Baba Bakala | C4: =VLOOKUP(B:B,Courts!B:C,2,FALSE()) -> 4 | D4: =VLOOKUP(B:B,Courts!B:E,4,FALSE()) -> 1 | E4: =VLOOKUP(B:B,Courts!B:D,3,FALSE()) -> 0 | F4: 1 | G4: 2 | H4: 1 | I4: 1 | J4: 1 | K4: =SUM(F4:I4) -> 5 | L4: =SUM(C4:E4)*1 -> 5 | M4: =K4-L4 -> 0 | N4: 0
A5: 4 | B5: Barnala | C5: =VLOOKUP(B:B,Courts!B:C,2,FALSE()) -> 11 | D5: =VLOOKUP(B:B,Courts!B:E,4,FALSE()) -> 0 | E5: =VLOOKUP(B:B,Courts!B:D,3,FALSE()) -> 0 | F5: 7 | G5: 3 | H5: 1 | I5: 2 | J5: 1 | K5: =SUM(F5:I5) -> 13 | L5: =SUM(C5:E5)*1 -> 11 | M5: =K5-L5 -> 2 | N5: 0
A6: 5 | B6: Bathinda | C6: =VLOOKUP(B:B,Courts!B:C,2,FALSE()) -> 25 | D6: =VLOOKUP(B:B,Courts!B:E,4,FALSE()) -> 0 | E6: =VLOOKUP(B:B,Courts!B:D,3,FALSE()) -> 0 | F6: 19 | G6: 0 | H6: 0 | I6: 9 | J6: 1 | K6: =SUM(F6:I6) -> 28 | L6: =SUM(C6:E6)*1 -> 25 | M6: =K6-L6 -> 3 | N6: 0
A7: 6 | B7: Talwandi Sabo | C7: =VLOOKUP(B:B,Courts!B:C,2,FALSE()) -> 6 | D7: =VLOOKUP(B:B,Courts!B:E,4,FALSE()) -> 1 | E7: =VLOOKUP(B:B,Courts!B:D,3,FALSE()) -> 0 | F7: 2 | G7: 2 | H7: 0 | I7: 3 | J7: 1 | K7: =SUM(F7:I7) -> 7 | L7: =SUM(C7:E7)*1 -> 7 | M7: =K7-L7 -> 0 | N7: 0
A8: 7 | B8: Phul | C8: =VLOOKUP(B:B,Courts!B:C,2,FALSE()) -> 4 | D8: =VLOOKUP(B:B,Courts!B:E,4,FALSE()) -> 1 | E8: =VLOOKUP(B:B,Courts!B:D,3,FALSE()) -> 0 | F8: 2 | G8: 1 | H8: 0 | I8: 3 | J8: 1 | K8: =SUM(F8:I8) -> 6 | L8: =SUM(C8:E8)*1 -> 5 | M8: =K8-L8 -> 1 | N8: 0
A9: 8 | B9: Faridkot | C9: =VLOOKUP(B:B,Courts!B:C,2,FALSE()) -> 12 | D9: =VLOOKUP(B:B,Courts!B:E,4,FALSE()) -> 0 | E9: =VLOOKUP(B:B,Courts!B:D,3,FALSE()) -> 0 | F9: 11 | G9: 0 | H9: 0 | I9: 1 | J9: 1 | K9: =SUM(F9:I9) -> 12 | L9: =SUM(C9:E9)*1 -> 12 | M9: =K9-L9 -> 0 | N9: 0
A10: 9 | B10: Jaitu | C10: =VLOOKUP(B:B,Courts!B:C,2,FALSE()) -> 2 | D10: =VLOOKUP(B:B,Courts!B:E,4,FALSE()) -> 0 | E10: =VLOOKUP(B:B,Courts!B:D,3,FALSE()) -> 0 | F10: 1 | G10: 0 | H10: 0 | I10: 1 | J10: 1 | K10: =SUM(F10:I10) -> 2 | L10: =SUM(C10:E10)*1 -> 2 | M10: =K10-L10 -> 0 | N10: 0
A11: 10 | B11: Fatehgarh Sahib | C11: =VLOOKUP(B:B,Courts!B:C,2,FALSE()) -> 11 | D11: =VLOOKUP(B:B,Courts!B:E,4,FALSE()) -> 0 | E11: =VLOOKUP(B:B,Courts!B:D,3,FALSE()) -> 0 | F11: 11 | G11: 0 | H11: 1 | I11: 1 | J11: 1 | K11: =SUM(F11:I11) -> 13 | L11: =SUM(C11:E11)*1 -> 11 | M11: =K11-L11 -> 2 | N11: 0
A12: 11 | B12: Amloh | C12: =VLOOKUP(B:B,Courts!B:C,2,FALSE()) -> 4 | D12: =VLOOKUP(B:B,Courts!B:E,4,FALSE()) -> 1 | E12: =VLOOKUP(B:B,Courts!B:D,3,FALSE()) -> 0 | F12: 2 | G12: 1 | H12: 1 | I12: 2 | J12: 1 | K12: =SUM(F12:I12) -> 6 | L12: =SUM(C12:E12)*1 -> 5 | M12: =K12-L12 -> 1 | N12: 0
A13: 12 | B13: Khamanon | C13: =VLOOKUP(B:B,Courts!B:C,2,FALSE()) -> 2 | D13: =VLOOKUP(B:B,Courts!B:E,4,FALSE()) -> 1 | E13: =VLOOKUP(B:B,Courts!B:D,3,FALSE()) -> 0 | F13: 1 | G13: 1 | H13: 1 | I13: 0 | J13: 1 | K13: =SUM(F13:I13) -> 3 | L13: =SUM(C13:E13)*1 -> 3 | M13: =K13-L13 -> 0 | N13: 0
... A24: 23 | B24: Mukerian | C24: =VLOOKUP(B:B,Courts!B:C,2,FALSE()) -> 3 | D24: =VLOOKUP(B:B,Courts!B:E,4,FALSE()) -> 1 | E24: =VLOOKUP(B:B,Courts!B:D,3,FALSE()) -> 0 | F24: 2 | G24: 1 | H24: 0 | I24: 2 | J24: 1 | K24: =SUM(F24:I24) -> 5 | L24: =SUM(C24:E24)*1 -> 4 | M24: =K24-L24 -> 1 | N24: 0
A25: 24 | B25: Garhshankar | C25: =VLOOKUP(B:B,Courts!B:C,2,FALSE()) -> 3 | D25: =VLOOKUP(B:B,Courts!B:E,4,FALSE()) -> 1 | E25: =VLOOKUP(B:B,Courts!B:D,3,FALSE()) -> 0 | F25: 3 | G25: 1 | H25: 0 | I25: 0 | J25: 1 | K25: =SUM(F25:I25) -> 4 | L25: =SUM(C25:E25)*1 -> 4 | M25: 0 | N25: 0
A26: 25 | B26: Jalandhar | C26: =VLOOKUP(B:B,Courts!B:C,2,FALSE()) -> 45 | D26: =VLOOKUP(B:B,Courts!B:E,4,FALSE()) -> 0 | E26: =VLOOKUP(B:B,Courts!B:D,3,FALSE()) -> 0 | F26: 35 | G26: 5 | H26: 0 | I26: 4 | J26: 1 | K26: =SUM(F26:I26) -> 44 | L26: =SUM(C26:E26)*1 -> 45 | M26: =K26-L26 -> -1 | N26: 0
A27: 26 | B27: Nakodar | C27: =VLOOKUP(B:B,Courts!B:C,2,FALSE()) -> 3 | D27: =VLOOKUP(B:B,Courts!B:E,4,FALSE()) -> 1 | E27: =VLOOKUP(B:B,Courts!B:D,3,FALSE()) -> 0 | F27: 4 | G27: 0 | H27: 0 | I27: 0 | J27: 1 | K27: =SUM(F27:I27) -> 4 | L27: =SUM(C27:E27)*1 -> 4 | M27: =K27-L27 -> 0 | N27: 0
A28: 27 | B28: Phillaur | C28: =VLOOKUP(B:B,Courts!B:C,2,FALSE()) -> 5 | D28: =VLOOKUP(B:B,Courts!B:E,4,FALSE()) -> 1 | E28: =VLOOKUP(B:B,Courts!B:D,3,FALSE()) -> 0 | F28: 4 | G28: 1 | H28: 0 | I28: 2 | J28: 1 | K28: =SUM(F28:I28) -> 7 | L28: =SUM(C28:E28)*1 -> 6 | M28: =K28-L28 -> 1 | N28: 0
A29: 28 | B29: Kapurthala | C29: =VLOOKUP(B:B,Courts!B:C,2,FALSE()) -> 10 | D29: =VLOOKUP(B:B,Courts!B:E,4,FALSE()) -> 0 | E29: =VLOOKUP(B:B,Courts!B:D,3,FALSE()) -> 0 | F29: 12 | G29: 0 | H29: 1 | I29: 0 | J29: 1 | K29: =SUM(F29:I29) -> 13 | L29: =SUM(C29:E29)*1 -> 10 | M29: =K29-L29 -> 3 | N29: 0
A30: 29 | B30: Phagwara | C30: =VLOOKUP(B:B,Courts!B:C,2,FALSE()) -> 4 | D30: =VLOOKUP(B:B,Courts!B:E,4,FALSE()) -> 1 | E30: =VLOOKUP(B:B,Courts!B:D,3,FALSE()) -> 0 | F30: 3 | G30: 1 | H30: 1 | I30: 1 | J30: 1 | K30: =SUM(F30:I30) -> 6 | L30: =SUM(C30:E30)*1 -> 5 | M30: =K30-L30 -> 1 | N30: 0
A31: 30 | B31: Sultanpur Lodhi | C31: =VLOOKUP(B:B,Courts!B:C,2,FALSE()) -> 3 | D31: =VLOOKUP(B:B,Courts!B:E,4,FALSE()) -> 1 | E31: =VLOOKUP(B:B,Courts!B:D,3,FALSE()) -> 0 | F31: 2 | G31: 0 | H31: 1 | I31: 1 | J31: 1 | K31: =SUM(F31:I31) -> 4 | L31: =SUM(C31:E31)*1 -> 4 | M31: =K31-L31 -> 0 | N31: 0
A32: 31 | B32: Bholath | C32: =VLOOKUP(B:B,Courts!B:C,2,FALSE()) -> 1 | D32: =VLOOKUP(B:B,Courts!B:E,4,FALSE()) -> 1 | E32: =VLOOKUP(B:B,Courts!B:D,3,FALSE()) -> 0 | F32: 0 | G32: 1 | H32: 1 | I32: 1 | J32: 1 | K32: =SUM(F32:I32) -> 3 | L32: =SUM(C32:E32)*1 -> 2 | M32: =K32-L32 -> 1 | N32: 0
A33: 32 | B33: Ludhiana | C33: =VLOOKUP(B:B,Courts!B:C,2,FALSE()) -> 73 | D33: =VLOOKUP(B:B,Courts!B:E,4,FALSE()) -> 0 | E33: =VLOOKUP(B:B,Courts!B:D,3,FALSE()) -> 0 | F33: 56 | G33: 2 | H33: 6 | I33: 12 | J33: 1 | K33: =SUM(F33:I33) -> 76 | L33: =SUM(C33:E33)*1 -> 73 | M33: =K33-L33 -> 3 | N33: 0
A34: 33 | B34: Samrala | C34: =VLOOKUP(B:B,Courts!B:C,2,FALSE()) -> 3 | D34: =VLOOKUP(B:B,Courts!B:E,4,FALSE()) -> 1 | E34: =VLOOKUP(B:B,Courts!B:D,3,FALSE()) -> 0 | F34: 3 | G34: 1 | H34: 0 | I34: 0 | J34: 1 | K34: =SUM(F34:I34) -> 4 | L34: =SUM(C34:E34)*1 -> 4 | M34: =K34-L34 -> 0 | N34: 0
A35: 34 | B35: Khanna | C35: =VLOOKUP(B:B,Courts!B:C,2,FALSE()) -> 4 | D35: =VLOOKUP(B:B,Courts!B:E,4,FALSE()) -> 1 | E35: =VLOOKUP(B:B,Courts!B:D,3,FALSE()) -> 0 | F35: 3 | G35: 2 | H35: 0 | I35: 0 | J35: 1 | K35: =SUM(F35:I35) -> 5 | L35: =SUM(C35:E35)*1 -> 5 | M35: =K35-L35 -> 0 | N35: 0
A36: 35 | B36: Jagraon | C36: =VLOOKUP(B:B,Courts!B:C,2,FALSE()) -> 6 | D36: =VLOOKUP(B:B,Courts!B:E,4,FALSE()) -> 1 | E36: =VLOOKUP(B:B,Courts!B:D,3,FALSE()) -> 0 | F36: 5 | G36: 1 | H36: 0 | I36: 2 | J36: 1 | K36: =SUM(F36:I36) -> 8 | L36: =SUM(C36:E36)*1 -> 7 | M36: =K36-L36 -> 1 | N36: 0
A37: 36 | B37: Payal | C37: =VLOOKUP(B:B,Courts!B:C,2,FALSE()) -> 3 | D37: =VLOOKUP(B:B,Courts!B:E,4,FALSE()) -> 1 | E37: =VLOOKUP(B:B,Courts!B:D,3,FALSE()) -> 0 | F37: 2 | G37: 1 | H37: 0 | I37: 1 | J37: 1 | K37: =SUM(F37:I37) -> 4 | L37: =SUM(C37:E37)*1 -> 4 | M37: =K37-L37 -> 0 | N37: 0
... A131: 130 | B131: Bilaspur | C131: =VLOOKUP(B:B,Courts!B:C,2,FALSE()) -> 4 | D131: =VLOOKUP(B:B,Courts!B:E,4,FALSE()) -> 1 | E131: =VLOOKUP(B:B,Courts!B:D,3,FALSE()) -> 2 | F131: 3 | G131: 2 | H131: 0 | I131: 0 | J131: 1 | K131: =SUM(F131:I131) -> 5 | L131: =SUM(C131:E131)*1 -> 7 | M131: =K131-L131 -> -2 | N131: 2
B133: Total | C133: =SUM(C2:C131) -> 1147 | D133: =SUM(D2:D131) -> 81 | E133: =SUM(E2:E131) -> 108 | F133: =SUM(F2:F131) -> 931 | G133: =SUM(G2:G131) -> 96 | H133: =SUM(H2:H131) -> 55 | I133: =SUM(I2:I131) -> 214 | J133: =SUM(J2:J131) -> 123 | ... N133: =SUM(N2:N131) -> 83
A135: 1 | B135: Punjab | C135: =SUM(C2:C69) -> 640 | D135: =SUM(D2:D69) -> 45 | E135: =SUM(E2:E69) -> 0 | F135: =SUM(F2:F69) -> 476 | G135: =SUM(G2:G69) -> 57 | H135: =SUM(H2:H69) -> 45 | I135: =SUM(I2:I69) -> 139 | J135: =SUM(J2:J69) -> 66 | ... N135: =SUM(N2:N69) -> 3
A136: 2 | B136: Haryana | C136: =SUM(C71:C131) -> 479 | D136: =SUM(D71:D131) -> 36 | E136: =SUM(E71:E131) -> 108 | F136: =SUM(F71:F131) -> 426 | G136: =SUM(G71:G131) -> 39 | H136: =SUM(H71:H131) -> 9 | I136: =SUM(I71:I131) -> 74 | J136: =SUM(J71:J131) -> 56 | ... N136: =SUM(N71:N131) -> 80
A137: 3 | B137: Chandigarh | C137: =SUM(C70) -> 28 | D137: =SUM(D70) -> 0 | E137: =SUM(E70) -> 0 | F137: =SUM(F70) -> 29 | G137: =SUM(G70) -> 0 | H137: =SUM(H70) -> 1 | I137: =SUM(I70) -> 1 | J137: =SUM(J70) -> 1 | ... N137: =SUM(N70) -> 0
B138: =B133 -> Total | C138: =SUM(C135:C137) -> 1147 | D138: =SUM(D135:D137) -> 81 | E138: =SUM(E135:E137) -> 108 | F138: =SUM(F135:F137) -> 931 | G138: =SUM(G135:G137) -> 96 | H138: =SUM(H135:H137) -> 55 | I138: =SUM(I135:I137) -> 214 | J138: =SUM(J135:J137) -> 123 | ... N138: =SUM(N135:N137) -> 83

Sheet AIO
A1: Sr. No. | B1: Sessions Division/Sub-Division | C1: Total number of working Court including family Courts (excluding Officers working as Secy, DLSA, ADJ/ ACJ as Spl. Judge, CBI Court & SJM, POIT/ Special Tribunal/ Railway Magistrate) as on 28.11.2025 | D1: TJOs | E1: Number of family Camp Court/ Gram Nyayalaya updated as on 28.11.2025 | F1: 2016 | G1: 2018 | H1: 2020 | I1: 2021 Paperless Court | J1: 2023 | K1: eSewa 2023 | L1: Help Desk 2023 | M1: Family Camp Courtrs & Gram Nyayalya (4 per Court) 2023 | N1: 1828 in 2023 | O1: Total distributed in 2023 | P1: Total distributed for COURTS | Q1: Requirement - Court use | R1: Requirement - TJO | S1: Requirement - Family & Gram Nyayalya | T1: Total Requirement | U1: Shortfall (-) / Surplus (+) | V1: Requirment after adjustment within Distt
A2: 1 | B2: Amritsar | C2: =VLOOKUP(B:B,Courts!B:C,2,FALSE()) -> 48 | D2: =VLOOKUP(B:B,Courts!B:D,3,FALSE()) -> 0 | E2: =VLOOKUP(B:B,Courts!B:E,4,FALSE()) -> 0 | F2: 136 | G2: 0 | H2: 29 | I2: 0 | J2: 96 | K2: 4 | L2: 4 | M2: 0 | N2: 19 | O2: =SUM(J2:N2) -> 123 | P2: =F2+G2+H2+I2+J2+M2+N2 -> 280 | Q2: =C2*8 -> 384 | R2: =D2*8 -> 0 | S2: =E2*4 -> 0 | T2: =SUM(Q2:S2) -> 384 | U2: =P2-T2 -> -104 | V2: -104
A3: 2 | B3: Ajnala | C3: =VLOOKUP(B:B,Courts!B:C,2,FALSE()) -> 5 | D3: =VLOOKUP(B:B,Courts!B:D,3,FALSE()) -> 0 | E3: =VLOOKUP(B:B,Courts!B:E,4,FALSE()) -> 1 | F3: 16 | G3: 0 | H3: 7 | I3: 0 | J3: 9 | K3: 1 | L3: 0 | M3: 4 | N3: 0 | O3: =SUM(J3:N3) -> 14 | P3: =F3+G3+H3+I3+J3+M3+N3 -> 36 | Q3: =C3*8 -> 40 | R3: =D3*8 -> 0 | S3: =E3*4 -> 4 | T3: =SUM(Q3:S3) -> 44 | U3: =P3-T3 -> -8 | V3: -8
A4: 3 | B4: Baba Bakala | C4: =VLOOKUP(B:B,Courts!B:C,2,FALSE()) -> 4 | D4: =VLOOKUP(B:B,Courts!B:D,3,FALSE()) -> 0 | E4: =VLOOKUP(B:B,Courts!B:E,4,FALSE()) -> 1 | F4: 4 | G4: 0 | H4: 11 | I4: 0 | J4: 0 | K4: 1 | L4: 0 | M4: 4 | N4: 2 | O4: =SUM(J4:N4) -> 7 | P4: =F4+G4+H4+I4+J4+M4+N4 -> 21 | Q4: =C4*8 -> 32 | R4: =D4*8 -> 0 | S4: =E4*4 -> 4 | T4: =SUM(Q4:S4) -> 36 | U4: =P4-T4 -> -15 | V4: -15
A5: 4 | B5: Barnala | C5: =VLOOKUP(B:B,Courts!B:C,2,FALSE()) -> 11 | D5: =VLOOKUP(B:B,Courts!B:D,3,FALSE()) -> 0 | E5: =VLOOKUP(B:B,Courts!B:E,4,FALSE()) -> 0 | F5: 32 | G5: 0 | H5: 17 | I5: 0 | J5: 25 | K5: 1 | L5: 2 | M5: 0 | N5: 14 | O5: =SUM(J5:N5) -> 42 | P5: =F5+G5+H5+I5+J5+M5+N5 -> 88 | Q5: =C5*8 -> 88 | R5: =D5*8 -> 0 | S5: =E5*4 -> 0 | T5: =SUM(Q5:S5) -> 88 | U5: =P5-T5 -> 0 | V5: 0
A6: 5 | B6: Bathinda | C6: =VLOOKUP(B:B,Courts!B:C,2,FALSE()) -> 25 | D6: =VLOOKUP(B:B,Courts!B:D,3,FALSE()) -> 0 | E6: =VLOOKUP(B:B,Courts!B:E,4,FALSE()) -> 0 | F6: 72 | G6: 0 | H6: 23 | I6: 0 | J6: 56 | K6: 3 | L6: 3 | M6: 0 | N6: 17 | O6: =SUM(J6:N6) -> 79 | P6: =F6+G6+H6+I6+J6+M6+N6 -> 168 | Q6: =C6*8 -> 200 | R6: =D6*8 -> 0 | S6: =E6*4 -> 0 | T6: =SUM(Q6:S6) -> 200 | U6: =P6-T6 -> -32 | V6: -32
A7: 6 | B7: Talwandi Sabo | C7: =VLOOKUP(B:B,Courts!B:C,2,FALSE()) -> 6 | D7: =VLOOKUP(B:B,Courts!B:D,3,FALSE()) -> 0 | E7: =VLOOKUP(B:B,Courts!B:E,4,FALSE()) -> 1 | F7: 8 | G7: 0 | H7: 12 | I7: 0 | J7: 1 | K7: 1 | L7: 0 | M7: 4 | N7: 3 | O7: =SUM(J7:N7) -> 9 | P7: =F7+G7+H7+I7+J7+M7+N7 -> 28 | Q7: =C7*8 -> 48 | R7: =D7*8 -> 0 | S7: =E7*4 -> 4 | T7: =SUM(Q7:S7) -> 52 | U7: =P7-T7 -> -24 | V7: -24
A8: 7 | B8: Phul | C8: =VLOOKUP(B:B,Courts!B:C,2,FALSE()) -> 4 | D8: =VLOOKUP(B:B,Courts!B:D,3,FALSE()) -> 0 | E8: =VLOOKUP(B:B,Courts!B:E,4,FALSE()) -> 1 | F8: 8 | G8: 0 | H8: 6 | I8: 0 | J8: 0 | K8: 1 | L8: 0 | M8: 4 | N8: 3 | O8: =SUM(J8:N8) -> 8 | P8: =F8+G8+H8+I8+J8+M8+N8 -> 21 | Q8: =C8*8 -> 32 | R8: =D8*8 -> 0 | S8: =E8*4 -> 4 | T8: =SUM(Q8:S8) -> 36 | U8: =P8-T8 -> -15 | V8: -15
A9: 8 | B9: Faridkot | C9: =VLOOKUP(B:B,Courts!B:C,2,FALSE()) -> 12 | D9: =VLOOKUP(B:B,Courts!B:D,3,FALSE()) -> 0 | E9: =VLOOKUP(B:B,Courts!B:E,4,FALSE()) -> 0 | F9: 44 | G9: 0 | H9: 13 | I9: 0 | J9: 13 | K9: 3 | L9: 1 | M9: 0 | N9: 10 | O9: =SUM(J9:N9) -> 27 | P9: =F9+G9+H9+I9+J9+M9+N9 -> 80 | Q9: =C9*8 -> 96 | R9: =D9*8 -> 0 | S9: =E9*4 -> 0 | T9: =SUM(Q9:S9) -> 96 | U9: =P9-T9 -> -16 | V9: -16
A10: 9 | B10: Jaitu | C10: =VLOOKUP(B:B,Courts!B:C,2,FALSE()) -> 2 | D10: =VLOOKUP(B:B,Courts!B:D,3,FALSE()) -> 0 | E10: =VLOOKUP(B:B,Courts!B:E,4,FALSE()) -> 0 | F10: 4 | G10: 0 | H10: 1 | I10: 0 | J10: 2 | K10: 2 | L10: 0 | M10: 0 | N10: 1 | O10: =SUM(J10:N10) -> 5 | P10: =F10+G10+H10+I10+J10+M10+N10 -> 8 | Q10: =C10*8 -> 16 | R10: =D10*8 -> 0 | S10: =E10*4 -> 0 | T10: =SUM(Q10:S10) -> 16 | U10: =P10-T10 -> -8 | V10: -8
A11: 10 | B11: Fatehgarh Sahib | C11: =VLOOKUP(B:B,Courts!B:C,2,FALSE()) -> 11 | D11: =VLOOKUP(B:B,Courts!B:D,3,FALSE()) -> 0 | E11: =VLOOKUP(B:B,Courts!B:E,4,FALSE()) -> 0 | F11: 48 | G11: 0 | H11: 12 | I11: 0 | J11: 18 | K11: 3 | L11: 2 | M11: 4 | N11: 10 | O11: =SUM(J11:N11) -> 37 | P11: =F11+G11+H11+I11+J11+M11+N11 -> 92 | Q11: =C11*8 -> 88 | R11: =D11*8 -> 0 | S11: =E11*4 -> 0 | T11: =SUM(Q11:S11) -> 88 | U11: =P11-T11 -> 4 | V11: 0
A12: 11 | B12: Amloh | C12: =VLOOKUP(B:B,Courts!B:C,2,FALSE()) -> 4 | D12: =VLOOKUP(B:B,Courts!B:D,3,FALSE()) -> 0 | E12: =VLOOKUP(B:B,Courts!B:E,4,FALSE()) -> 1 | F12: 8 | G12: 0 | H12: 7 | I12: 0 | J12: 9 | K12: 1 | L12: 0 | M12: 4 | N12: 0 | O12: =SUM(J12:N12) -> 14 | P12: =F12+G12+H12+I12+J12+M12+N12 -> 28 | Q12: =C12*8 -> 32 | R12: =D12*8 -> 0 | S12: =E12*4 -> 4 | T12: =SUM(Q12:S12) -> 36 | U12: =P12-T12 -> -8 | V12: -4
A13: 12 | B13: Khamanon | C13: =VLOOKUP(B:B,Courts!B:C,2,FALSE()) -> 2 | D13: =VLOOKUP(B:B,Courts!B:D,3,FALSE()) -> 0 | E13: =VLOOKUP(B:B,Courts!B:E,4,FALSE()) -> 1 | F13: 4 | G13: 0 | H13: 6 | I13: 0 | J13: 6 | K13: 1 | L13: 0 | M13: 4 | N13: 0 | O13: =SUM(J13:N13) -> 11 | P13: =F13+G13+H13+I13+J13+M13+N13 -> 20 | Q13: =C13*8 -> 16 | R13: =D13*8 -> 0 | S13: =E13*4 -> 4 | T13: =SUM(Q13:S13) -> 20 | U13: =P13-T13 -> 0 | V13: 0
... A86: 85 | B86: Hansi | C86: =VLOOKUP(B:B,Courts!B:C,2,FALSE()) -> 3 | D86: =VLOOKUP(B:B,Courts!B:D,3,FALSE()) -> 1 | E86: =VLOOKUP(B:B,Courts!B:E,4,FALSE()) -> 1 | F86: 16 | G86: 0 | H86: 7 | I86: 0 | J86: 0 | K86: 2 | L86: 0 | M86: 4 | N86: 12 | O86: =SUM(J86:N86) -> 18 | P86: =F86+G86+H86+I86+J86+M86+N86 -> 39 | Q86: =C86*8 -> 24 | R86: =D86*8 -> 8 | S86: =E86*4 -> 4 | T86: =SUM(Q86:S86) -> 36 | U86: =P86-T86 -> 3 | V86: 0
A87: 86 | B87: Narnaud | C87: =VLOOKUP(B:B,Courts!B:C,2,FALSE()) -> 1 | D87: =VLOOKUP(B:B,Courts!B:D,3,FALSE()) -> 0 | E87: =VLOOKUP(B:B,Courts!B:E,4,FALSE()) -> 1 | F87: 0 | G87: 0 | H87: 0 | I87: 0 | J87: 0 | K87: 0 | L87: 0 | M87: 0 | N87: 0 | O87: 0 | P87: =F87+G87+H87+I87+J87+M87+N87 -> 0 | Q87: =C87*8 -> 8 | R87: =D87*8 -> 0 | S87: =E87*4 -> 4 | T87: =SUM(Q87:S87) -> 12 | U87: =P87-T87 -> -12
A88: 87 | B88: Barwala | C88: =VLOOKUP(B:B,Courts!B:C,2,FALSE()) -> 2 | D88: =VLOOKUP(B:B,Courts!B:D,3,FALSE()) -> 0 | E88: =VLOOKUP(B:B,Courts!B:E,4,FALSE()) -> 1 | F88: 0 | G88: 0 | H88: 0 | I88: 0 | J88: 0 | K88: 0 | L88: 0 | M88: 0 | N88: 0 | O88: 0 | P88: =F88+G88+H88+I88+J88+M88+N88 -> 0 | Q88: =C88*8 -> 16 | R88: =D88*8 -> 0 | S88: =E88*4 -> 4 | T88: =SUM(Q88:S88) -> 20 | U88: =P88-T88 -> -20
A89: 88 | B89: Jhajjar | C89: =VLOOKUP(B:B,Courts!B:C,2,FALSE()) -> 11 | D89: =VLOOKUP(B:B,Courts!B:D,3,FALSE()) -> 2 | E89: =VLOOKUP(B:B,Courts!B:E,4,FALSE()) -> 0 | F89: 60 | G89: 0 | H89: 11 | I89: 0 | J89: 0 | K89: 1 | L89: 1 | M89: 0 | N89: 31 | O89: =SUM(J89:N89) -> 33 | P89: =F89+G89+H89+I89+J89+M89+N89 -> 102 | Q89: =C89*8 -> 88 | R89: =D89*8 -> 16 | S89: =E89*4 -> 0 | T89: =SUM(Q89:S89) -> 104 | U89: =P89-T89 -> -2 | V89: -2
A90: 89 | B90: Bahadurgarh | C90: =VLOOKUP(B:B,Courts!B:C,2,FALSE()) -> 4 | D90: =VLOOKUP(B:B,Courts!B:D,3,FALSE()) -> 2 | E90: =VLOOKUP(B:B,Courts!B:E,4,FALSE()) -> 1 | F90: 20 | G90: 0 | H90: 9 | I90: 0 | J90: 3 | K90: 1 | L90: 0 | M90: 4 | N90: 16 | O90: =SUM(J90:N90) -> 24 | P90: =F90+G90+H90+I90+J90+M90+N90 -> 52 | Q90: =C90*8 -> 32 | R90: =D90*8 -> 16 | S90: =E90*4 -> 4 | T90: =SUM(Q90:S90) -> 52 | U90: =P90-T90 -> 0 | V90: 0
A91: 90 | B91: Jind | C91: =VLOOKUP(B:B,Courts!B:C,2,FALSE()) -> 10 | D91: =VLOOKUP(B:B,Courts!B:D,3,FALSE()) -> 3 | E91: =VLOOKUP(B:B,Courts!B:E,4,FALSE()) -> 0 | F91: 48 | G91: 0 | H91: 13 | I91: 0 | J91: 19 | K91: 5 | L91: 2 | M91: 0 | N91: 16 | O91: =SUM(J91:N91) -> 42 | P91: =F91+G91+H91+I91+J91+M91+N91 -> 96 | Q91: =C91*8 -> 80 | R91: =D91*8 -> 24 | S91: =E91*4 -> 0 | T91: =SUM(Q91:S91) -> 104 | U91: =P91-T91 -> -8 | V91: -8
A92: 91 | B92: Narwana | C92: =VLOOKUP(B:B,Courts!B:C,2,FALSE()) -> 2 | D92: =VLOOKUP(B:B,Courts!B:D,3,FALSE()) -> 1 | E92: =VLOOKUP(B:B,Courts!B:E,4,FALSE()) -> 1 | F92: 12 | G92: 0 | H92: 7 | I92: 0 | J92: 5 | K92: 1 | L92: 0 | M92: 4 | N92: 0 | O92: =SUM(J92:N92) -> 10 | P92: =F92+G92+H92+I92+J92+M92+N92 -> 28 | Q92: =C92*8 -> 16 | R92: =D92*8 -> 8 | S92: =E92*4 -> 4 | T92: =SUM(Q92:S92) -> 28 | U92: =P92-T92 -> 0 | V92: 0
A93: 92 | B93: Safidon | C93: =VLOOKUP(B:B,Courts!B:C,2,FALSE()) -> 2 | D93: =VLOOKUP(B:B,Courts!B:D,3,FALSE()) -> 1 | E93: =VLOOKUP(B:B,Courts!B:E,4,FALSE()) -> 1 | F93: 8 | G93: 0 | H93: 6 | I93: 0 | J93: 2 | K93: 1 | L93: 0 | M93: 4 | N93: 0 | O93: =SUM(J93:N93) -> 7 | P93: =F93+G93+H93+I93+J93+M93+N93 -> 20 | Q93: =C93*8 -> 16 | R93: =D93*8 -> 8 | S93: =E93*4 -> 4 | T93: =SUM(Q93:S93) -> 28 | U93: =P93-T93 -> -8 | V93: -8
A94: 93 | B94: Kaithal | C94: =VLOOKUP(B:B,Courts!B:C,2,FALSE()) -> 15 | D94: =VLOOKUP(B:B,Courts!B:D,3,FALSE()) -> 4 | E94: =VLOOKUP(B:B,Courts!B:E,4,FALSE()) -> 0 | F94: 56 | G94: 0 | H94: 13 | I94: 0 | J94: 12 | K94: 3 | L94: 2 | M94: 0 | N94: 47 | O94: =SUM(J94:N94) -> 64 | P94: =F94+G94+H94+I94+J94+M94+N94 -> 128 | Q94: =C94*8 -> 120 | R94: =D94*8 -> 32 | S94: =E94*4 -> 0 | T94: =SUM(Q94:S94) -> 152 | U94: =P94-T94 -> -24 | V94: -24
A95: 94 | B95: Guhla | C95: =VLOOKUP(B:B,Courts!B:C,2,FALSE()) -> 2 | D95: =VLOOKUP(B:B,Courts!B:D,3,FALSE()) -> 0 | E95: =VLOOKUP(B:B,Courts!B:E,4,FALSE()) -> 1 | F95: 4 | G95: 0 | H95: 6 | I95: 0 | J95: 4 | K95: 1 | L95: 0 | M95: 4 | N95: 2 | O95: =SUM(J95:N95) -> 11 | P95: =F95+G95+H95+I95+J95+M95+N95 -> 20 | Q95: =C95*8 -> 16 | R95: =D95*8 -> 0 | S95: =E95*4 -> 4 | T95: =SUM(Q95:S95) -> 20 | U95: =P95-T95 -> 0 | V95: 0
A96: 95 | B96: Karnal | C96: =VLOOKUP(B:B,Courts!B:C,2,FALSE()) -> 26 | D96: =VLOOKUP(B:B,Courts!B:D,3,FALSE()) -> 7 | E96: =VLOOKUP(B:B,Courts!B:E,4,FALSE()) -> 0 | F96: 92 | G96: 0 | H96: 19 | I96: 0 | J96: 1 | K96: 5 | L96: 2 | M96: 0 | N96: 120 | O96: =SUM(J96:N96) -> 128 | P96: =F96+G96+H96+I96+J96+M96+N96 -> 232 | Q96: =C96*8 -> 208 | R96: =D96*8 -> 56 | S96: =E96*4 -> 0 | T96: =SUM(Q96:S96) -> 264 | U96: =P96-T96 -> -32 | V96: -28
A97: 96 | B97: Assandh | C97: =VLOOKUP(B:B,Courts!B:C,2,FALSE()) -> 2 | D97: =VLOOKUP(B:B,Courts!B:D,3,FALSE()) -> 0 | E97: =VLOOKUP(B:B,Courts!B:E,4,FALSE()) -> 1 | F97: 8 | G97: 0 | H97: 6 | I97: 0 | J97: 0 | K97: 2 | L97: 0 | M97: 4 | N97: 10 | O97: =SUM(J97:N97) -> 16 | P97: =F97+G97+H97+I97+J97+M97+N97 -> 28 | Q97: =C97*8 -> 16 | R97: =D97*8 -> 0 | S97: =E97*4 -> 4 | T97: =SUM(Q97:S97) -> 20 | U97: =P97-T97 -> 8 | V97: 0
A98: 97 | B98: Gharaunda | C98: =VLOOKUP(B:B,Courts!B:C,2,FALSE()) -> 1 | D98: =VLOOKUP(B:B,Courts!B:D,3,FALSE()) -> 0 | E98: =VLOOKUP(B:B,Courts!B:E,4,FALSE()) -> 0 | F98: 0 | G98: 0 | H98: 0 | I98: 0 | J98: 0 | K98: 0 | L98: 0 | M98: 0 | N98: 0 | O98: =SUM(J98:N98) -> 0 | P98: =F98+G98+H98+I98+J98+M98+N98 -> 0 | Q98: =C98*8 -> 8 | R98: =D98*8 -> 0 | S98: =E98*4 -> 0 | T98: =SUM(Q98:S98) -> 8 | U98: =P98-T98 -> -8 | V98: 0
A99: 98 | B99: Indri | C99: =VLOOKUP(B:B,Courts!B:C,2,FALSE()) -> 1 | D99: =VLOOKUP(B:B,Courts!B:D,3,FALSE()) -> 0 | E99: =VLOOKUP(B:B,Courts!B:E,4,FALSE()) -> 1 | F99: 4 | G99: 0 | H99: 6 | I99: 0 | J99: 6 | K99: 2 | L99: 0 | M99: 0 | N99: 0 | O99: =SUM(J99:N99) -> 8 | P99: =F99+G99+H99+I99+J99+M99+N99 -> 16 | Q99: =C99*8 -> 8 | R99: =D99*8 -> 0 | S99: =E99*4 -> 4 | T99: =SUM(Q99:S99) -> 12 | U99: =P99-T99 -> 4 | V99: 0
A100: 99 | B100: Kurukshetra | C100: =VLOOKUP(B:B,Courts!B:C,2,FALSE()) -> 15 | D100: =VLOOKUP(B:B,Courts!B:D,3,FALSE()) -> 1 | E100: =VLOOKUP(B:B,Courts!B:E,4,FALSE()) -> 0 | F100: 60 | G100: 0 | H100: 17 | I100: 0 | J100: 26 | K100: 3 | L100: 2 | M100: 0 | N100: 41 | O100: =SUM(J100:N100) -> 72 | P100: =F100+G100+H100+I100+J100+M100+N100 -> 144 | Q100: =C100*8 -> 120 | R100: =D100*8 -> 8 | S100: =E100*4 -> 0 | T100: =SUM(Q100:S100) -> 128 | U100: =P100-T100 -> 16 | V100: 0
... A131: 130 | B131: Bilaspur | C131: =VLOOKUP(B:B,Courts!B:C,2,FALSE()) -> 4 | D131: =VLOOKUP(B:B,Courts!B:D,3,FALSE()) -> 2 | E131: =VLOOKUP(B:B,Courts!B:E,4,FALSE()) -> 1 | F131: 16 | G131: 0 | H131: 8 | I131: 0 | J131: 0 | K131: 1 | L131: 0 | M131: 4 | N131: 22 | O131: =SUM(J131:N131) -> 27 | P131: =F131+G131+H131+I131+J131+M131+N131 -> 50 | Q131: =C131*8 -> 32 | R131: =D131*8 -> 16 | S131: =E131*4 -> 4 | T131: =SUM(Q131:S131) -> 52 | U131: =P131-T131 -> -2 | V131: 0
B133: Total | C133: =SUM(C2:C132) -> 1147 | D133: =SUM(D2:D132) -> 108 | E133: =SUM(E2:E132) -> 81 | F133: =SUM(F2:F132) -> 3784 | G133: =SUM(G2:G132) -> 1 | H133: =SUM(H2:H132) -> 1524 | I133: =SUM(I2:I132) -> 18 | J133: =SUM(J2:J132) -> 1422 | ... V133: =SUM(V2:V132) -> -1489
A135: 1 | B135: Punjab | C135: =SUM(C2:C69) -> 640 | D135: =SUM(D2:D69) -> 0 | E135: =SUM(E2:E69) -> 45 | F135: =SUM(F2:F69) -> 1944 | G135: =SUM(G2:G69) -> 0 | H135: =SUM(H2:H69) -> 840 | I135: =SUM(I2:I69) -> 9 | J135: =SUM(J2:J69) -> 998 | ... V135: =SUM(V2:V69) -> -890
A136: 2 | B136: Haryana | C136: =SUM(C71:C131) -> 479 | D136: =SUM(D71:D131) -> 108 | E136: =SUM(E71:E131) -> 36 | F136: =SUM(F71:F131) -> 1724 | G136: =SUM(G71:G131) -> 1 | H136: =SUM(H71:H131) -> 657 | I136: =SUM(I71:I131) -> 6 | J136: =SUM(J71:J131) -> 420 | ... V136: =SUM(V71:V131) -> -599
A137: 3 | B137: Chandigarh | C137: =SUM(C70) -> 28 | D137: =SUM(D70) -> 0 | E137: =SUM(E70) -> 0 | F137: =SUM(F70) -> 116 | G137: =SUM(G70) -> 0 | H137: =SUM(H70) -> 27 | I137: =SUM(I70) -> 3 | J137: =SUM(J70) -> 4 | ... V137: =SUM(V70) -> 0
B138: Total | C138: =SUM(C135:C137) -> 1147 | D138: =SUM(D135:D137) -> 108 | E138: =SUM(E135:E137) -> 81 | F138: =SUM(F135:F137) -> 3784 | G138: =SUM(G135:G137) -> 1 | H138: =SUM(H135:H137) -> 1524 | I138: =SUM(I135:I137) -> 18 | J138: =SUM(J135:J137) -> 1422 | ... V138: =SUM(V135:V137) -> -1489

Sheet DLP
A1: Sr. No. | B1: Sessions Division/Sub-Division | C1: Total number of working Court including family Courts (excluding Officers working as Secy, DLSA, ADJ/ ACJ as Spl. Judge, CBI Court & SJM, POIT/ Special Tribunal) as on 28.11.2025 | D1: Number of family Camp Court/ Gram Nyayalaya updated as on 28.11.2025 | E1: TJOs | F1: AMC 2014 (HP - 1566) | G1: AMC 2014 (HP - 1022) | H1: AMC 2014 Samsung ML 2161 | I1: 2016 (Actual) | J1: AMC - faulty | K1: (Qty.) 2016- Under AMC | L1: (Qty.) 2020 - Under warranty | M1: (Qty.) 2025 - Admn work | N1: (Qty.) 2025 - Court use | O1: Total available (under warranty & AMC) | P1: Requirement 2 per Court | Q1: NO DLP for family camp Court as per new norms | R1: Total Requirement for Courts | S1: Shortfall (-) / Surplus (+) | T1: Req after adjustment within District
A2: 1 | B2: Amritsar | C2: =VLOOKUP(B:B,Courts!B:C,2,FALSE()) -> 48 | D2: =VLOOKUP(B:B,Courts!B:E,4,FALSE()) -> 0 | E2: =VLOOKUP(B:B,Courts!B:D,3,FALSE()) -> 0 | F2: 28 | G2: 1 | H2: 24 | I2: 68 | K2: =I2-J2 -> 68 | L2: 16 | M2: 39 | N2: 6 | O2: =K2+L2+N2 -> 90 | P2: =SUM(C2+E2)*2 -> 96 | Q2: =D2*1 -> 0 | R2: =SUM(P2:Q2) -> 96 | S2: =O2-R2 -> -6 | T2: 5
A3: 2 | B3: Ajnala | C3: =VLOOKUP(B:B,Courts!B:C,2,FALSE()) -> 5 | D3: =VLOOKUP(B:B,Courts!B:E,4,FALSE()) -> 1 | E3: =VLOOKUP(B:B,Courts!B:D,3,FALSE()) -> 0 | I3: 8 | K3: =I3-J3 -> 8 | L3: 3 | M3: 3 | N3: 0 | O3: =K3+L3+N3 -> 11 | P3: =SUM(C3+E3)*2 -> 10 | Q3: 0 | R3: =SUM(P3:Q3) -> 10 | S3: =O3-R3 -> 1 | T3: =IF(S3<0, -S3, 0) -> 0
A4: 3 | B4: Baba Bakala | C4: =VLOOKUP(B:B,Courts!B:C,2,FALSE()) -> 4 | D4: =VLOOKUP(B:B,Courts!B:E,4,FALSE()) -> 1 | E4: =VLOOKUP(B:B,Courts!B:D,3,FALSE()) -> 0 | F4: 2 | I4: 2 | K4: =I4-J4 -> 2 | L4: 5 | M4: 4 | N4: 1 | O4: =K4+L4+N4 -> 8 | P4: =SUM(C4+E4)*2 -> 8 | Q4: 0 | R4: =SUM(P4:Q4) -> 8 | S4: =O4-R4 -> 0 | T4: =IF(S4<0, -S4, 0) -> 0
A5: 4 | B5: Barnala | C5: =VLOOKUP(B:B,Courts!B:C,2,FALSE()) -> 11 | D5: =VLOOKUP(B:B,Courts!B:E,4,FALSE()) -> 0 | E5: =VLOOKUP(B:B,Courts!B:D,3,FALSE()) -> 0 | F5: 14 | I5: 16 | J5: 1 | K5: =I5-J5 -> 15 | L5: 9 | M5: 13 | N5: 2 | O5: =K5+L5+N5 -> 26 | P5: =SUM(C5+E5)*2 -> 22 | Q5: 0 | R5: =SUM(P5:Q5) -> 22 | S5: =O5-R5 -> 4 | T5: =IF(S5<0, -S5, 0) -> 0
A6: 5 | B6: Bathinda | C6: =VLOOKUP(B:B,Courts!B:C,2,FALSE()) -> 25 | D6: =VLOOKUP(B:B,Courts!B:E,4,FALSE()) -> 0 | E6: =VLOOKUP(B:B,Courts!B:D,3,FALSE()) -> 0 | F6: 17 | I6: 36 | K6: =I6-J6 -> 36 | L6: 11 | M6: 25 | N6: 7 | O6: =K6+L6+N6 -> 54 | P6: =SUM(C6+E6)*2 -> 50 | Q6: 0 | R6: =SUM(P6:Q6) -> 50 | S6: =O6-R6 -> 4 | T6: =IF(S6<0, -S6, 0) -> 0
A7: 6 | B7: Talwandi Sabo | C7: =VLOOKUP(B:B,Courts!B:C,2,FALSE()) -> 6 | D7: =VLOOKUP(B:B,Courts!B:E,4,FALSE()) -> 1 | E7: =VLOOKUP(B:B,Courts!B:D,3,FALSE()) -> 0 | F7: 2 | I7: 4 | J7: 2 | K7: =I7-J7 -> 2 | L7: 5 | M7: 4 | N7: 5 | O7: =K7+L7+N7 -> 12 | P7: =SUM(C7+E7)*2 -> 12 | Q7: 0 | R7: =SUM(P7:Q7) -> 12 | S7: =O7-R7 -> 0 | T7: =IF(S7<0, -S7, 0) -> 0
A8: 7 | B8: Phul | C8: =VLOOKUP(B:B,Courts!B:C,2,FALSE()) -> 4 | D8: =VLOOKUP(B:B,Courts!B:E,4,FALSE()) -> 1 | E8: =VLOOKUP(B:B,Courts!B:D,3,FALSE()) -> 0 | F8: 2 | I8: 4 | K8: =I8-J8 -> 4 | L8: 3 | M8: 2 | N8: 3 | O8: =K8+L8+N8 -> 10 | P8: =SUM(C8+E8)*2 -> 8 | Q8: 0 | R8: =SUM(P8:Q8) -> 8 | S8: =O8-R8 -> 2 | T8: =IF(S8<0, -S8, 0) -> 0
A9: 8 | B9: Faridkot | C9: =VLOOKUP(B:B,Courts!B:C,2,FALSE()) -> 12 | D9: =VLOOKUP(B:B,Courts!B:E,4,FALSE()) -> 0 | E9: =VLOOKUP(B:B,Courts!B:D,3,FALSE()) -> 0 | F9: 10 | I9: 22 | K9: =I9-J9 -> 22 | L9: 5 | M9: 14 | N9: 0 | O9: =K9+L9+N9 -> 27 | P9: =SUM(C9+E9)*2 -> 24 | Q9: 0 | R9: =SUM(P9:Q9) -> 24 | S9: =O9-R9 -> 3 | T9: =IF(S9<0, -S9, 0) -> 0
